Workbook

Sheet Instructions
B1: AF Training Services Pro Forma
B3: You are responsible for inputting all assumptions based on your own business strategy and decisions. The data in the charts below is derived from the assumptions you input. This data is for illustrative purposes only; your actual revenue and ROI may vary significantly. We do not make any representations about a franchisee's future financial performance or the past financial performance of these operations. We also do not authorize our employees or representatives to make any such representations either orally or in writing
B5: This Pro Forma should be used as you consider adding Training Services into your operations. The assumptions and charts below are to be used for: AF HIIT, AF Strong, AF GTR, and 1:1 Personal Training (30/60m).
B7: Step 1: Go to Inputs tab and fill in all the peach colored cells
B9: Step 2: Go to any of the light blue colored tabs to view profit calculators

Sheet Inputs
B2: Session Details | C2: 30 Min 1:1 | D2: 60 Min 1:1 | E2: AF Strong | F2: AF HIIT | G2: GTR | J2: Input Cell, please fill in
B3: Average Members Per Session | J3: Formula Cell, leave as is
B4: Session Capacity | I4: GTR | J4: Group Training Recovery
B5: Percentage Capacity
B6: Price Per Session Per Member
B7: Time (Hours)
B9: Weekly Number of Sessions | C9: 30 Min 1:1 | D9: 60 Min 1:1 | E9: AF Strong | F9: AF HIIT | G9: GTR
B10: PT Manager
B11: Coach 1
B12: Coach 2
B13: Coach 3
B14: Coach 4
B15: Total Sessions | C15: =SUM(C10:C14) -> 0 | D15: =SUM(D10:D14) -> 0 | E15: =SUM(E10:E14) -> 0 | F15: =SUM(F10:F14) -> 0 | G15: =SUM(G10:G14) -> 0
B17: Bonus/Commisions % of Total Revenue | C17: 30 Min 1:1 | D17: 60 Min 1:1 | E17: AF Strong | F17: AF HIIT | G17: GTR
B18: PT Manager
B19: Coach 1
B20: Coach 2
B21: Coach 3
B22: Coach 4
B24: COGS | C24: Hourly Rate | D24: Non-Coaching Hours | E24: Coaching Hours | F24: Weekly Hours
B25: PT Manager
B26: Coach 1
B27: Coach 2
B28: Coach 3
B29: Coach 4

Sheet Session
B2: Session Averages | C2: 30 Min 1:1 | D2: 60 Min 1:1 | E2: AF Strong | F2: AF HIIT | G2: GTR
B4: Revenue
B5: PT Manager | C5: =IF(Inputs!C10>0,Inputs!C$3*Inputs!C$6,0) -> 0 | D5: =IF(Inputs!D10>0,Inputs!D$3*Inputs!D$6,0) -> 0 | E5: =IF(Inputs!E10>0,Inputs!E$3*Inputs!E$6,0) -> 0 | F5: =IF(Inputs!F10>0,Inputs!F$3*Inputs!F$6,0) -> 0 | G5: =IF(Inputs!G10>0,Inputs!G$3*Inputs!G$6,0) -> 0
B6: Coach 1 | C6: =IF(Inputs!C11>0,Inputs!C$3*Inputs!C$6,0) -> 0 | D6: =IF(Inputs!D11>0,Inputs!D$3*Inputs!D$6,0) -> 0 | E6: =IF(Inputs!E11>0,Inputs!E$3*Inputs!E$6,0) -> 0 | F6: =IF(Inputs!F11>0,Inputs!F$3*Inputs!F$6,0) -> 0 | G6: =IF(Inputs!G11>0,Inputs!G$3*Inputs!G$6,0) -> 0
B7: Coach 2 | C7: =IF(Inputs!C12>0,Inputs!C$3*Inputs!C$6,0) -> 0 | D7: =IF(Inputs!D12>0,Inputs!D$3*Inputs!D$6,0) -> 0 | E7: =IF(Inputs!E12>0,Inputs!E$3*Inputs!E$6,0) -> 0 | F7: =IF(Inputs!F12>0,Inputs!F$3*Inputs!F$6,0) -> 0 | G7: =IF(Inputs!G12>0,Inputs!G$3*Inputs!G$6,0) -> 0
B8: Coach 3 | C8: =IF(Inputs!C13>0,Inputs!C$3*Inputs!C$6,0) -> 0 | D8: =IF(Inputs!D13>0,Inputs!D$3*Inputs!D$6,0) -> 0 | E8: =IF(Inputs!E13>0,Inputs!E$3*Inputs!E$6,0) -> 0 | F8: =IF(Inputs!F13>0,Inputs!F$3*Inputs!F$6,0) -> 0 | G8: =IF(Inputs!G13>0,Inputs!G$3*Inputs!G$6,0) -> 0
B9: Coach 4 | C9: =IF(Inputs!C14>0,Inputs!C$3*Inputs!C$6,0) -> 0 | D9: =IF(Inputs!D14>0,Inputs!D$3*Inputs!D$6,0) -> 0 | E9: =IF(Inputs!E14>0,Inputs!E$3*Inputs!E$6,0) -> 0 | F9: =IF(Inputs!F14>0,Inputs!F$3*Inputs!F$6,0) -> 0 | G9: =IF(Inputs!G14>0,Inputs!G$3*Inputs!G$6,0) -> 0
B11: Commission
B12: PT Manager | C12: =IF(Inputs!C10>0,C5*Inputs!C18,0) -> 0 | D12: =IF(Inputs!D10>0,D5*Inputs!D18,0) -> 0 | E12: =IF(Inputs!E10>0,E5*Inputs!E18,0) -> 0 | F12: =IF(Inputs!F10>0,F5*Inputs!F18,0) -> 0 | G12: =IF(Inputs!G10>0,G5*Inputs!G18,0) -> 0
B13: Coach 1 | C13: =IF(Inputs!C11>0,C6*Inputs!C19,0) -> 0 | D13: =IF(Inputs!D11>0,D6*Inputs!D19,0) -> 0 | E13: =IF(Inputs!E11>0,E6*Inputs!E19,0) -> 0 | F13: =IF(Inputs!F11>0,F6*Inputs!F19,0) -> 0 | G13: =IF(Inputs!G11>0,G6*Inputs!G19,0) -> 0
B14: Coach 2 | C14: =IF(Inputs!C12>0,C7*Inputs!C20,0) -> 0 | D14: =IF(Inputs!D12>0,D7*Inputs!D20,0) -> 0 | E14: =IF(Inputs!E12>0,E7*Inputs!E20,0) -> 0 | F14: =IF(Inputs!F12>0,F7*Inputs!F20,0) -> 0 | G14: =IF(Inputs!G12>0,G7*Inputs!G20,0) -> 0
B15: Coach 3 | C15: =IF(Inputs!C13>0,C8*Inputs!C21,0) -> 0 | D15: =IF(Inputs!D13>0,D8*Inputs!D21,0) -> 0 | E15: =IF(Inputs!E13>0,E8*Inputs!E21,0) -> 0 | F15: =IF(Inputs!F13>0,F8*Inputs!F21,0) -> 0 | G15: =IF(Inputs!G13>0,G8*Inputs!G21,0) -> 0
B16: Coach 4 | C16: =IF(Inputs!C14>0,C9*Inputs!C22,0) -> 0 | D16: =IF(Inputs!D14>0,D9*Inputs!D22,0) -> 0 | E16: =IF(Inputs!E14>0,E9*Inputs!E22,0) -> 0 | F16: =IF(Inputs!F14>0,F9*Inputs!F22,0) -> 0 | G16: =IF(Inputs!G14>0,G9*Inputs!G22,0) -> 0
B18: Profit
B19: PT Manager | C19: =IF(Inputs!C10>0,C5-C12,0) -> 0 | D19: =IF(Inputs!D10>0,D5-D12,0) -> 0 | E19: =IF(Inputs!E10>0,E5-E12,0) -> 0 | F19: =IF(Inputs!F10>0,F5-F12,0) -> 0 | G19: =IF(Inputs!G10>0,G5-G12,0) -> 0
B20: Coach 1 | C20: =IF(Inputs!C11>0,C6-C13,0) -> 0 | D20: =IF(Inputs!D11>0,D6-D13,0) -> 0 | E20: =IF(Inputs!E11>0,E6-E13,0) -> 0 | F20: =IF(Inputs!F11>0,F6-F13,0) -> 0 | G20: =IF(Inputs!G11>0,G6-G13,0) -> 0
B21: Coach 2 | C21: =IF(Inputs!C12>0,C7-C14,0) -> 0 | D21: =IF(Inputs!D12>0,D7-D14,0) -> 0 | E21: =IF(Inputs!E12>0,E7-E14,0) -> 0 | F21: =IF(Inputs!F12>0,F7-F14,0) -> 0 | G21: =IF(Inputs!G12>0,G7-G14,0) -> 0
B22: Coach 3 | C22: =IF(Inputs!C13>0,C8-C15,0) -> 0 | D22: =IF(Inputs!D13>0,D8-D15,0) -> 0 | E22: =IF(Inputs!E13>0,E8-E15,0) -> 0 | F22: =IF(Inputs!F13>0,F8-F15,0) -> 0 | G22: =IF(Inputs!G13>0,G8-G15,0) -> 0
B23: Coach 4 | C23: =IF(Inputs!C14>0,C9-C16,0) -> 0 | D23: =IF(Inputs!D14>0,D9-D16,0) -> 0 | E23: =IF(Inputs!E14>0,E9-E16,0) -> 0 | F23: =IF(Inputs!F14>0,F9-F16,0) -> 0 | G23: =IF(Inputs!G14>0,G9-G16,0) -> 0
B25: Profit %
B26: PT Manager | C26: =IFERROR(C19/C5,0) -> 0 | D26: =IFERROR(D19/D5,0) -> 0 | E26: =IFERROR(E19/E5,0) -> 0 | F26: =IFERROR(F19/F5,0) -> 0 | G26: =IFERROR(G19/G5,0) -> 0
B27: Coach 1 | C27: =IFERROR(C20/C6,0) -> 0 | D27: =IFERROR(D20/D6,0) -> 0 | E27: =IFERROR(E20/E6,0) -> 0 | F27: =IFERROR(F20/F6,0) -> 0 | G27: =IFERROR(G20/G6,0) -> 0
B28: Coach 2 | C28: =IFERROR(C21/C7,0) -> 0 | D28: =IFERROR(D21/D7,0) -> 0 | E28: =IFERROR(E21/E7,0) -> 0 | F28: =IFERROR(F21/F7,0) -> 0 | G28: =IFERROR(G21/G7,0) -> 0
B29: Coach 3 | C29: =IFERROR(C22/C8,0) -> 0 | D29: =IFERROR(D22/D8,0) -> 0 | E29: =IFERROR(E22/E8,0) -> 0 | F29: =IFERROR(F22/F8,0) -> 0 | G29: =IFERROR(G22/G8,0) -> 0
B30: Coach 4 | C30: =IFERROR(C23/C9,0) -> 0 | D30: =IFERROR(D23/D9,0) -> 0 | E30: =IFERROR(E23/E9,0) -> 0 | F30: =IFERROR(F23/F9,0) -> 0 | G30: =IFERROR(G23/G9,0) -> 0
B32: *Profit excludes hourly wages

Sheet Weekly
B2: Weekly Totals | C2: 30 Min 1:1 | D2: 60 Min 1:1 | E2: AF Strong | F2: AF HIIT | G2: GTR | H2: Total | I2: Trainer %
B4: Revenue
B5: PT Manager | C5: =Inputs!C$3*Inputs!C$6*Inputs!C10 -> 0 | D5: =Inputs!D$3*Inputs!D$6*Inputs!D10 -> 0 | E5: =Inputs!E$3*Inputs!E$6*Inputs!E10 -> 0 | F5: =Inputs!F$3*Inputs!F$6*Inputs!F10 -> 0 | G5: =Inputs!G$3*Inputs!G$6*Inputs!G10 -> 0 | H5: =SUM(C5:G5) -> 0 | I5: =IFERROR(SUM(C5:G5)/SUM(C$5:G$9),0) -> 0
B6: Coach 1 | C6: =Inputs!C$3*Inputs!C$6*Inputs!C11 -> 0 | D6: =Inputs!D$3*Inputs!D$6*Inputs!D11 -> 0 | E6: =Inputs!E$3*Inputs!E$6*Inputs!E11 -> 0 | F6: =Inputs!F$3*Inputs!F$6*Inputs!F11 -> 0 | G6: =Inputs!G$3*Inputs!G$6*Inputs!G11 -> 0 | H6: =SUM(C6:G6) -> 0 | I6: =IFERROR(SUM(C6:G6)/SUM(C$5:G$9),0) -> 0
B7: Coach 2 | C7: =Inputs!C$3*Inputs!C$6*Inputs!C12 -> 0 | D7: =Inputs!D$3*Inputs!D$6*Inputs!D12 -> 0 | E7: =Inputs!E$3*Inputs!E$6*Inputs!E12 -> 0 | F7: =Inputs!F$3*Inputs!F$6*Inputs!F12 -> 0 | G7: =Inputs!G$3*Inputs!G$6*Inputs!G12 -> 0 | H7: =SUM(C7:G7) -> 0 | I7: =IFERROR(SUM(C7:G7)/SUM(C$5:G$9),0) -> 0
B8: Coach 3 | C8: =Inputs!C$3*Inputs!C$6*Inputs!C13 -> 0 | D8: =Inputs!D$3*Inputs!D$6*Inputs!D13 -> 0 | E8: =Inputs!E$3*Inputs!E$6*Inputs!E13 -> 0 | F8: =Inputs!F$3*Inputs!F$6*Inputs!F13 -> 0 | G8: =Inputs!G$3*Inputs!G$6*Inputs!G13 -> 0 | H8: =SUM(C8:G8) -> 0 | I8: =IFERROR(SUM(C8:G8)/SUM(C$5:G$9),0) -> 0
B9: Coach 4 | C9: =Inputs!C$3*Inputs!C$6*Inputs!C14 -> 0 | D9: =Inputs!D$3*Inputs!D$6*Inputs!D14 -> 0 | E9: =Inputs!E$3*Inputs!E$6*Inputs!E14 -> 0 | F9: =Inputs!F$3*Inputs!F$6*Inputs!F14 -> 0 | G9: =Inputs!G$3*Inputs!G$6*Inputs!G14 -> 0 | H9: =SUM(C9:G9) -> 0 | I9: =IFERROR(SUM(C9:G9)/SUM(C$5:G$9),0) -> 0
B10: Total Revenue | C10: =SUM(C5:C9) -> 0 | D10: =SUM(D5:D9) -> 0 | E10: =SUM(E5:E9) -> 0 | F10: =SUM(F5:F9) -> 0 | G10: =SUM(G5:G9) -> 0 | H10: =SUM(H5:H9) -> 0
B11: % | C11: =IFERROR(SUM(C5:C9)/SUM($C$5:$G$9),0) -> 0 | D11: =IFERROR(SUM(D5:D9)/SUM($C$5:$G$9),0) -> 0 | E11: =IFERROR(SUM(E5:E9)/SUM($C$5:$G$9),0) -> 0 | F11: =IFERROR(SUM(F5:F9)/SUM($C$5:$G$9),0) -> 0 | G11: =IFERROR(SUM(G5:G9)/SUM($C$5:$G$9),0) -> 0
B13: Wages
B14: PT Manager | H14: =Inputs!C25*Inputs!D25 -> 0 | I14: =IFERROR(SUM(D14:H14)/SUM(D$14:H$18),0) -> 0
B15: Coach 1 | H15: =Inputs!C26*Inputs!D26 -> 0 | I15: =IFERROR(SUM(D15:H15)/SUM(D$14:H$18),0) -> 0
B16: Coach 2 | H16: =Inputs!C27*Inputs!D27 -> 0 | I16: =IFERROR(SUM(D16:H16)/SUM(D$14:H$18),0) -> 0
B17: Coach 3 | H17: =Inputs!C28*Inputs!D28 -> 0 | I17: =IFERROR(SUM(D17:H17)/SUM(D$14:H$18),0) -> 0
B18: Coach 4 | H18: =Inputs!C29*Inputs!D29 -> 0 | I18: =IFERROR(SUM(D18:H18)/SUM(D$14:H$18),0) -> 0
B19: Total Wages | H19: =SUM(H14:H18) -> 0
B20: %
B22: Commission
B23: PT Manager | C23: =C5*Inputs!C18 -> 0 | D23: =D5*Inputs!D18 -> 0 | E23: =E5*Inputs!E18 -> 0 | F23: =F5*Inputs!F18 -> 0 | G23: =G5*Inputs!G18 -> 0 | H23: =SUM(C23:G23) -> 0 | I23: =IFERROR(SUM(C23:G23)/SUM(C$23:G$27),0) -> 0
B24: Coach 1 | C24: =C6*Inputs!C19 -> 0 | D24: =D6*Inputs!D19 -> 0 | E24: =E6*Inputs!E19 -> 0 | F24: =F6*Inputs!F19 -> 0 | G24: =G6*Inputs!G19 -> 0 | H24: =SUM(C24:G24) -> 0 | I24: =IFERROR(SUM(C24:G24)/SUM(C$23:G$27),0) -> 0
B25: Coach 2 | C25: =C7*Inputs!C20 -> 0 | D25: =D7*Inputs!D20 -> 0 | E25: =E7*Inputs!E20 -> 0 | F25: =F7*Inputs!F20 -> 0 | G25: =G7*Inputs!G20 -> 0 | H25: =SUM(C25:G25) -> 0 | I25: =IFERROR(SUM(C25:G25)/SUM(C$23:G$27),0) -> 0
B26: Coach 3 | C26: =C8*Inputs!C21 -> 0 | D26: =D8*Inputs!D21 -> 0 | E26: =E8*Inputs!E21 -> 0 | F26: =F8*Inputs!F21 -> 0 | G26: =G8*Inputs!G21 -> 0 | H26: =SUM(C26:G26) -> 0 | I26: =IFERROR(SUM(C26:G26)/SUM(C$23:G$27),0) -> 0
B27: Coach 4 | C27: =C9*Inputs!C22 -> 0 | D27: =D9*Inputs!D22 -> 0 | E27: =E9*Inputs!E22 -> 0 | F27: =F9*Inputs!F22 -> 0 | G27: =G9*Inputs!G22 -> 0 | H27: =SUM(C27:G27) -> 0 | I27: =IFERROR(SUM(C27:G27)/SUM(C$23:G$27),0) -> 0
B28: Total Commision | C28: =SUM(C23:C27) -> 0 | D28: =SUM(D23:D27) -> 0 | E28: =SUM(E23:E27) -> 0 | F28: =SUM(F23:F27) -> 0 | G28: =SUM(G23:G27) -> 0 | H28: =SUM(H23:H27) -> 0
B29: % | C29: =IFERROR(SUM(C23:C27)/SUM($C$23:$G$27),0) -> 0 | D29: =IFERROR(SUM(D23:D27)/SUM($C$23:$G$27),0) -> 0 | E29: =IFERROR(SUM(E23:E27)/SUM($C$23:$G$27),0) -> 0 | F29: =IFERROR(SUM(F23:F27)/SUM($C$23:$G$27),0) -> 0 | G29: =IFERROR(SUM(G23:G27)/SUM($C$23:$G$27),0) -> 0
B31: Profit
B32: PT Manager | C32: =C5-C14-C23 -> 0 | D32: =D5-D14-D23 -> 0 | E32: =E5-E14-E23 -> 0 | F32: =F5-F14-F23 -> 0 | G32: =G5-G14-G23 -> 0 | H32: =H5-H14-H23 -> 0 | I32: =IFERROR(SUM(C32:G32)/SUM(C$32:G$36),0) -> 0
B33: Coach 1 | C33: =C6-C15-C24 -> 0 | D33: =D6-D15-D24 -> 0 | E33: =E6-E15-E24 -> 0 | F33: =F6-F15-F24 -> 0 | G33: =G6-G15-G24 -> 0 | H33: =H6-H15-H24 -> 0 | I33: =IFERROR(SUM(C33:G33)/SUM(C$32:G$36),0) -> 0
B34: Coach 2 | C34: =C7-C16-C25 -> 0 | D34: =D7-D16-D25 -> 0 | E34: =E7-E16-E25 -> 0 | F34: =F7-F16-F25 -> 0 | G34: =G7-G16-G25 -> 0 | H34: =H7-H16-H25 -> 0 | I34: =IFERROR(SUM(C34:G34)/SUM(C$32:G$36),0) -> 0
B35: Coach 3 | C35: =C8-C17-C26 -> 0 | D35: =D8-D17-D26 -> 0 | E35: =E8-E17-E26 -> 0 | F35: =F8-F17-F26 -> 0 | G35: =G8-G17-G26 -> 0 | H35: =H8-H17-H26 -> 0 | I35: =IFERROR(SUM(C35:G35)/SUM(C$32:G$36),0) -> 0
B36: Coach 4 | C36: =C9-C18-C27 -> 0 | D36: =D9-D18-D27 -> 0 | E36: =E9-E18-E27 -> 0 | F36: =F9-F18-F27 -> 0 | G36: =G9-G18-G27 -> 0 | H36: =H9-H18-H27 -> 0 | I36: =IFERROR(SUM(C36:G36)/SUM(C$32:G$36),0) -> 0
B37: Total Profit | C37: =SUM(C32:C36) -> 0 | D37: =SUM(D32:D36) -> 0 | E37: =SUM(E32:E36) -> 0 | F37: =SUM(F32:F36) -> 0 | G37: =SUM(G32:G36) -> 0 | H37: =SUM(H32:H36) -> 0
B38: % | C38: =IFERROR(SUM(C32:C36)/SUM($C$32:$G$36),0) -> 0 | D38: =IFERROR(SUM(D32:D36)/SUM($C$32:$G$36),0) -> 0 | E38: =IFERROR(SUM(E32:E36)/SUM($C$32:$G$36),0) -> 0 | F38: =IFERROR(SUM(F32:F36)/SUM($C$32:$G$36),0) -> 0 | G38: =IFERROR(SUM(G32:G36)/SUM($C$32:$G$36),0) -> 0
B40: Total Profit % | H40: =IFERROR(H37/H10,0) -> 0

Sheet Monthly
B2: Monthly Totals | C2: 30 Min 1:1 | D2: 60 Min 1:1 | E2: AF Strong | F2: AF HIIT | G2: GTR | H2: Total | I2: Trainer %
B4: Revenue
B5: PT Manager | C5: =Inputs!C$3*Inputs!C$6*Inputs!C10*52/12 -> 0 | D5: =Inputs!D$3*Inputs!D$6*Inputs!D10*52/12 -> 0 | E5: =Inputs!E$3*Inputs!E$6*Inputs!E10*52/12 -> 0 | F5: =Inputs!F$3*Inputs!F$6*Inputs!F10*52/12 -> 0 | G5: =Inputs!G$3*Inputs!G$6*Inputs!G10*52/12 -> 0 | H5: =SUM(C5:G5) -> 0 | I5: =IFERROR(SUM(C5:G5)/SUM(C$5:G$9),0) -> 0
B6: Coach 1 | C6: =Inputs!C$3*Inputs!C$6*Inputs!C11*52/12 -> 0 | D6: =Inputs!D$3*Inputs!D$6*Inputs!D11*52/12 -> 0 | E6: =Inputs!E$3*Inputs!E$6*Inputs!E11*52/12 -> 0 | F6: =Inputs!F$3*Inputs!F$6*Inputs!F11*52/12 -> 0 | G6: =Inputs!G$3*Inputs!G$6*Inputs!G11*52/12 -> 0 | H6: =SUM(C6:G6) -> 0 | I6: =IFERROR(SUM(C6:G6)/SUM(C$5:G$9),0) -> 0
B7: Coach 2 | C7: =Inputs!C$3*Inputs!C$6*Inputs!C12*52/12 -> 0 | D7: =Inputs!D$3*Inputs!D$6*Inputs!D12*52/12 -> 0 | E7: =Inputs!E$3*Inputs!E$6*Inputs!E12*52/12 -> 0 | F7: =Inputs!F$3*Inputs!F$6*Inputs!F12*52/12 -> 0 | G7: =Inputs!G$3*Inputs!G$6*Inputs!G12*52/12 -> 0 | H7: =SUM(C7:G7) -> 0 | I7: =IFERROR(SUM(C7:G7)/SUM(C$5:G$9),0) -> 0
B8: Coach 3 | C8: =Inputs!C$3*Inputs!C$6*Inputs!C13*52/12 -> 0 | D8: =Inputs!D$3*Inputs!D$6*Inputs!D13*52/12 -> 0 | E8: =Inputs!E$3*Inputs!E$6*Inputs!E13*52/12 -> 0 | F8: =Inputs!F$3*Inputs!F$6*Inputs!F13*52/12 -> 0 | G8: =Inputs!G$3*Inputs!G$6*Inputs!G13*52/12 -> 0 | H8: =SUM(C8:G8) -> 0 | I8: =IFERROR(SUM(C8:G8)/SUM(C$5:G$9),0) -> 0
B9: Coach 4 | C9: =Inputs!C$3*Inputs!C$6*Inputs!C14*52/12 -> 0 | D9: =Inputs!D$3*Inputs!D$6*Inputs!D14*52/12 -> 0 | E9: =Inputs!E$3*Inputs!E$6*Inputs!E14*52/12 -> 0 | F9: =Inputs!F$3*Inputs!F$6*Inputs!F14*52/12 -> 0 | G9: =Inputs!G$3*Inputs!G$6*Inputs!G14*52/12 -> 0 | H9: =SUM(C9:G9) -> 0 | I9: =IFERROR(SUM(C9:G9)/SUM(C$5:G$9),0) -> 0
B10: Total Revenue | C10: =SUM(C5:C9) -> 0 | D10: =SUM(D5:D9) -> 0 | E10: =SUM(E5:E9) -> 0 | F10: =SUM(F5:F9) -> 0 | G10: =SUM(G5:G9) -> 0 | H10: =SUM(H5:H9) -> 0
B11: % | C11: =IFERROR(SUM(C5:C9)/SUM($C$5:$G$9),0) -> 0 | D11: =IFERROR(SUM(D5:D9)/SUM($C$5:$G$9),0) -> 0 | E11: =IFERROR(SUM(E5:E9)/SUM($C$5:$G$9),0) -> 0 | F11: =IFERROR(SUM(F5:F9)/SUM($C$5:$G$9),0) -> 0 | G11: =IFERROR(SUM(G5:G9)/SUM($C$5:$G$9),0) -> 0
B13: Wages
B14: PT Manager | H14: =Inputs!C25*Inputs!D25*52/12 -> 0 | I14: =IFERROR(SUM(D14:H14)/SUM(D$14:H$18),0) -> 0
B15: Coach 1 | H15: =Inputs!C26*Inputs!D26*52/12 -> 0 | I15: =IFERROR(SUM(D15:H15)/SUM(D$14:H$18),0) -> 0
B16: Coach 2 | H16: =Inputs!C27*Inputs!D27*52/12 -> 0 | I16: =IFERROR(SUM(D16:H16)/SUM(D$14:H$18),0) -> 0
B17: Coach 3 | H17: =Inputs!C28*Inputs!D28*52/12 -> 0 | I17: =IFERROR(SUM(D17:H17)/SUM(D$14:H$18),0) -> 0
B18: Coach 4 | H18: =Inputs!C29*Inputs!D29*52/12 -> 0 | I18: =IFERROR(SUM(D18:H18)/SUM(D$14:H$18),0) -> 0
B19: Total Wages | H19: =SUM(H14:H18) -> 0
B20: %
B22: Commission
B23: PT Manager | C23: =C5*Inputs!C18 -> 0 | D23: =D5*Inputs!D18 -> 0 | E23: =E5*Inputs!E18 -> 0 | F23: =F5*Inputs!F18 -> 0 | G23: =G5*Inputs!G18 -> 0 | H23: =SUM(C23:G23) -> 0 | I23: =IFERROR(SUM(C23:G23)/SUM(C$23:G$27),0) -> 0
B24: Coach 1 | C24: =C6*Inputs!C19 -> 0 | D24: =D6*Inputs!D19 -> 0 | E24: =E6*Inputs!E19 -> 0 | F24: =F6*Inputs!F19 -> 0 | G24: =G6*Inputs!G19 -> 0 | H24: =SUM(C24:G24) -> 0 | I24: =IFERROR(SUM(C24:G24)/SUM(C$23:G$27),0) -> 0
B25: Coach 2 | C25: =C7*Inputs!C20 -> 0 | D25: =D7*Inputs!D20 -> 0 | E25: =E7*Inputs!E20 -> 0 | F25: =F7*Inputs!F20 -> 0 | G25: =G7*Inputs!G20 -> 0 | H25: =SUM(C25:G25) -> 0 | I25: =IFERROR(SUM(C25:G25)/SUM(C$23:G$27),0) -> 0
B26: Coach 3 | C26: =C8*Inputs!C21 -> 0 | D26: =D8*Inputs!D21 -> 0 | E26: =E8*Inputs!E21 -> 0 | F26: =F8*Inputs!F21 -> 0 | G26: =G8*Inputs!G21 -> 0 | H26: =SUM(C26:G26) -> 0 | I26: =IFERROR(SUM(C26:G26)/SUM(C$23:G$27),0) -> 0
B27: Coach 4 | C27: =C9*Inputs!C22 -> 0 | D27: =D9*Inputs!D22 -> 0 | E27: =E9*Inputs!E22 -> 0 | F27: =F9*Inputs!F22 -> 0 | G27: =G9*Inputs!G22 -> 0 | H27: =SUM(C27:G27) -> 0 | I27: =IFERROR(SUM(C27:G27)/SUM(C$23:G$27),0) -> 0
B28: Total Commision | C28: =SUM(C23:C27) -> 0 | D28: =SUM(D23:D27) -> 0 | E28: =SUM(E23:E27) -> 0 | F28: =SUM(F23:F27) -> 0 | G28: =SUM(G23:G27) -> 0 | H28: =SUM(H23:H27) -> 0
B29: % | C29: =IFERROR(SUM(C23:C27)/SUM($C$23:$G$27),0) -> 0 | D29: =IFERROR(SUM(D23:D27)/SUM($C$23:$G$27),0) -> 0 | E29: =IFERROR(SUM(E23:E27)/SUM($C$23:$G$27),0) -> 0 | F29: =IFERROR(SUM(F23:F27)/SUM($C$23:$G$27),0) -> 0 | G29: =IFERROR(SUM(G23:G27)/SUM($C$23:$G$27),0) -> 0
B31: Profit
B32: PT Manager | C32: =C5-C14-C23 -> 0 | D32: =D5-D14-D23 -> 0 | E32: =E5-E14-E23 -> 0 | F32: =F5-F14-F23 -> 0 | G32: =G5-G14-G23 -> 0 | H32: =H5-H14-H23 -> 0 | I32: =IFERROR(SUM(C32:G32)/SUM(C$32:G$36),0) -> 0
B33: Coach 1 | C33: =C6-C15-C24 -> 0 | D33: =D6-D15-D24 -> 0 | E33: =E6-E15-E24 -> 0 | F33: =F6-F15-F24 -> 0 | G33: =G6-G15-G24 -> 0 | H33: =H6-H15-H24 -> 0 | I33: =IFERROR(SUM(C33:G33)/SUM(C$32:G$36),0) -> 0
B34: Coach 2 | C34: =C7-C16-C25 -> 0 | D34: =D7-D16-D25 -> 0 | E34: =E7-E16-E25 -> 0 | F34: =F7-F16-F25 -> 0 | G34: =G7-G16-G25 -> 0 | H34: =H7-H16-H25 -> 0 | I34: =IFERROR(SUM(C34:G34)/SUM(C$32:G$36),0) -> 0
B35: Coach 3 | C35: =C8-C17-C26 -> 0 | D35: =D8-D17-D26 -> 0 | E35: =E8-E17-E26 -> 0 | F35: =F8-F17-F26 -> 0 | G35: =G8-G17-G26 -> 0 | H35: =H8-H17-H26 -> 0 | I35: =IFERROR(SUM(C35:G35)/SUM(C$32:G$36),0) -> 0
B36: Coach 4 | C36: =C9-C18-C27 -> 0 | D36: =D9-D18-D27 -> 0 | E36: =E9-E18-E27 -> 0 | F36: =F9-F18-F27 -> 0 | G36: =G9-G18-G27 -> 0 | H36: =H9-H18-H27 -> 0 | I36: =IFERROR(SUM(C36:G36)/SUM(C$32:G$36),0) -> 0
B37: Total Profit | C37: =SUM(C32:C36) -> 0 | D37: =SUM(D32:D36) -> 0 | E37: =SUM(E32:E36) -> 0 | F37: =SUM(F32:F36) -> 0 | G37: =SUM(G32:G36) -> 0 | H37: =SUM(H32:H36) -> 0
B38: % | C38: =IFERROR(SUM(C32:C36)/SUM($C$32:$G$36),0) -> 0 | D38: =IFERROR(SUM(D32:D36)/SUM($C$32:$G$36),0) -> 0 | E38: =IFERROR(SUM(E32:E36)/SUM($C$32:$G$36),0) -> 0 | F38: =IFERROR(SUM(F32:F36)/SUM($C$32:$G$36),0) -> 0 | G38: =IFERROR(SUM(G32:G36)/SUM($C$32:$G$36),0) -> 0
B40: Total Profit % | H40: =IFERROR(H37/H10,0) -> 0

Sheet Annual
B2: Annual Totals | C2: 30 Min 1:1 | D2: 60 Min 1:1 | E2: AF Strong | F2: AF HIIT | G2: GTR | H2: Total | I2: Trainer %
B4: Revenue
B5: PT Manager | C5: =Inputs!C$3*Inputs!C$6*Inputs!C10*52 -> 0 | D5: =Inputs!D$3*Inputs!D$6*Inputs!D10*52 -> 0 | E5: =Inputs!E$3*Inputs!E$6*Inputs!E10*52 -> 0 | F5: =Inputs!F$3*Inputs!F$6*Inputs!F10*52 -> 0 | G5: =Inputs!G$3*Inputs!G$6*Inputs!G10*52 -> 0 | H5: =SUM(C5:G5) -> 0 | I5: =IFERROR(SUM(C5:G5)/SUM(C$5:G$9),0) -> 0
B6: Coach 1 | C6: =Inputs!C$3*Inputs!C$6*Inputs!C11*52 -> 0 | D6: =Inputs!D$3*Inputs!D$6*Inputs!D11*52 -> 0 | E6: =Inputs!E$3*Inputs!E$6*Inputs!E11*52 -> 0 | F6: =Inputs!F$3*Inputs!F$6*Inputs!F11*52 -> 0 | G6: =Inputs!G$3*Inputs!G$6*Inputs!G11*52 -> 0 | H6: =SUM(C6:G6) -> 0 | I6: =IFERROR(SUM(C6:G6)/SUM(C$5:G$9),0) -> 0
B7: Coach 2 | C7: =Inputs!C$3*Inputs!C$6*Inputs!C12*52 -> 0 | D7: =Inputs!D$3*Inputs!D$6*Inputs!D12*52 -> 0 | E7: =Inputs!E$3*Inputs!E$6*Inputs!E12*52 -> 0 | F7: =Inputs!F$3*Inputs!F$6*Inputs!F12*52 -> 0 | G7: =Inputs!G$3*Inputs!G$6*Inputs!G12*52 -> 0 | H7: =SUM(C7:G7) -> 0 | I7: =IFERROR(SUM(C7:G7)/SUM(C$5:G$9),0) -> 0
B8: Coach 3 | C8: =Inputs!C$3*Inputs!C$6*Inputs!C13*52 -> 0 | D8: =Inputs!D$3*Inputs!D$6*Inputs!D13*52 -> 0 | E8: =Inputs!E$3*Inputs!E$6*Inputs!E13*52 -> 0 | F8: =Inputs!F$3*Inputs!F$6*Inputs!F13*52 -> 0 | G8: =Inputs!G$3*Inputs!G$6*Inputs!G13*52 -> 0 | H8: =SUM(C8:G8) -> 0 | I8: =IFERROR(SUM(C8:G8)/SUM(C$5:G$9),0) -> 0
B9: Coach 4 | C9: =Inputs!C$3*Inputs!C$6*Inputs!C14*52 -> 0 | D9: =Inputs!D$3*Inputs!D$6*Inputs!D14*52 -> 0 | E9: =Inputs!E$3*Inputs!E$6*Inputs!E14*52 -> 0 | F9: =Inputs!F$3*Inputs!F$6*Inputs!F14*52 -> 0 | G9: =Inputs!G$3*Inputs!G$6*Inputs!G14*52 -> 0 | H9: =SUM(C9:G9) -> 0 | I9: =IFERROR(SUM(C9:G9)/SUM(C$5:G$9),0) -> 0
B10: Total Revenue | C10: =SUM(C5:C9) -> 0 | D10: =SUM(D5:D9) -> 0 | E10: =SUM(E5:E9) -> 0 | F10: =SUM(F5:F9) -> 0 | G10: =SUM(G5:G9) -> 0 | H10: =SUM(H5:H9) -> 0
B11: % | C11: =IFERROR(SUM(C5:C9)/SUM($C$5:$G$9),0) -> 0 | D11: =IFERROR(SUM(D5:D9)/SUM($C$5:$G$9),0) -> 0 | E11: =IFERROR(SUM(E5:E9)/SUM($C$5:$G$9),0) -> 0 | F11: =IFERROR(SUM(F5:F9)/SUM($C$5:$G$9),0) -> 0 | G11: =IFERROR(SUM(G5:G9)/SUM($C$5:$G$9),0) -> 0
B13: Wages
B14: PT Manager | H14: =Inputs!C25*Inputs!D25*52 -> 0 | I14: =IFERROR(SUM(D14:H14)/SUM(D$14:H$18),0) -> 0
B15: Coach 1 | H15: =Inputs!C26*Inputs!D26*52 -> 0 | I15: =IFERROR(SUM(D15:H15)/SUM(D$14:H$18),0) -> 0
B16: Coach 2 | H16: =Inputs!C27*Inputs!D27*52 -> 0 | I16: =IFERROR(SUM(D16:H16)/SUM(D$14:H$18),0) -> 0
B17: Coach 3 | H17: =Inputs!C28*Inputs!D28*52 -> 0 | I17: =IFERROR(SUM(D17:H17)/SUM(D$14:H$18),0) -> 0
B18: Coach 4 | H18: =Inputs!C29*Inputs!D29*52 -> 0 | I18: =IFERROR(SUM(D18:H18)/SUM(D$14:H$18),0) -> 0
B19: Total Wages | H19: =SUM(H14:H18) -> 0
B20: %
B22: Commission
B23: PT Manager | C23: =C5*Inputs!C18 -> 0 | D23: =D5*Inputs!D18 -> 0 | E23: =E5*Inputs!E18 -> 0 | F23: =F5*Inputs!F18 -> 0 | G23: =G5*Inputs!G18 -> 0 | H23: =SUM(C23:G23) -> 0 | I23: =IFERROR(SUM(C23:G23)/SUM(C$23:G$27),0) -> 0
B24: Coach 1 | C24: =C6*Inputs!C19 -> 0 | D24: =D6*Inputs!D19 -> 0 | E24: =E6*Inputs!E19 -> 0 | F24: =F6*Inputs!F19 -> 0 | G24: =G6*Inputs!G19 -> 0 | H24: =SUM(C24:G24) -> 0 | I24: =IFERROR(SUM(C24:G24)/SUM(C$23:G$27),0) -> 0
B25: Coach 2 | C25: =C7*Inputs!C20 -> 0 | D25: =D7*Inputs!D20 -> 0 | E25: =E7*Inputs!E20 -> 0 | F25: =F7*Inputs!F20 -> 0 | G25: =G7*Inputs!G20 -> 0 | H25: =SUM(C25:G25) -> 0 | I25: =IFERROR(SUM(C25:G25)/SUM(C$23:G$27),0) -> 0
B26: Coach 3 | C26: =C8*Inputs!C21 -> 0 | D26: =D8*Inputs!D21 -> 0 | E26: =E8*Inputs!E21 -> 0 | F26: =F8*Inputs!F21 -> 0 | G26: =G8*Inputs!G21 -> 0 | H26: =SUM(C26:G26) -> 0 | I26: =IFERROR(SUM(C26:G26)/SUM(C$23:G$27),0) -> 0
B27: Coach 4 | C27: =C9*Inputs!C22 -> 0 | D27: =D9*Inputs!D22 -> 0 | E27: =E9*Inputs!E22 -> 0 | F27: =F9*Inputs!F22 -> 0 | G27: =G9*Inputs!G22 -> 0 | H27: =SUM(C27:G27) -> 0 | I27: =IFERROR(SUM(C27:G27)/SUM(C$23:G$27),0) -> 0
B28: Total Commision | C28: =SUM(C23:C27) -> 0 | D28: =SUM(D23:D27) -> 0 | E28: =SUM(E23:E27) -> 0 | F28: =SUM(F23:F27) -> 0 | G28: =SUM(G23:G27) -> 0 | H28: =SUM(H23:H27) -> 0
B29: % | C29: =IFERROR(SUM(C23:C27)/SUM($C$23:$G$27),0) -> 0 | D29: =IFERROR(SUM(D23:D27)/SUM($C$23:$G$27),0) -> 0 | E29: =IFERROR(SUM(E23:E27)/SUM($C$23:$G$27),0) -> 0 | F29: =IFERROR(SUM(F23:F27)/SUM($C$23:$G$27),0) -> 0 | G29: =IFERROR(SUM(G23:G27)/SUM($C$23:$G$27),0) -> 0
B31: Profit
B32: PT Manager | C32: =C5-C14-C23 -> 0 | D32: =D5-D14-D23 -> 0 | E32: =E5-E14-E23 -> 0 | F32: =F5-F14-F23 -> 0 | G32: =G5-G14-G23 -> 0 | H32: =H5-H14-H23 -> 0 | I32: =IFERROR(SUM(C32:G32)/SUM(C$32:G$36),0) -> 0
B33: Coach 1 | C33: =C6-C15-C24 -> 0 | D33: =D6-D15-D24 -> 0 | E33: =E6-E15-E24 -> 0 | F33: =F6-F15-F24 -> 0 | G33: =G6-G15-G24 -> 0 | H33: =H6-H15-H24 -> 0 | I33: =IFERROR(SUM(C33:G33)/SUM(C$32:G$36),0) -> 0
B34: Coach 2 | C34: =C7-C16-C25 -> 0 | D34: =D7-D16-D25 -> 0 | E34: =E7-E16-E25 -> 0 | F34: =F7-F16-F25 -> 0 | G34: =G7-G16-G25 -> 0 | H34: =H7-H16-H25 -> 0 | I34: =IFERROR(SUM(C34:G34)/SUM(C$32:G$36),0) -> 0
B35: Coach 3 | C35: =C8-C17-C26 -> 0 | D35: =D8-D17-D26 -> 0 | E35: =E8-E17-E26 -> 0 | F35: =F8-F17-F26 -> 0 | G35: =G8-G17-G26 -> 0 | H35: =H8-H17-H26 -> 0 | I35: =IFERROR(SUM(C35:G35)/SUM(C$32:G$36),0) -> 0
B36: Coach 4 | C36: =C9-C18-C27 -> 0 | D36: =D9-D18-D27 -> 0 | E36: =E9-E18-E27 -> 0 | F36: =F9-F18-F27 -> 0 | G36: =G9-G18-G27 -> 0 | H36: =H9-H18-H27 -> 0 | I36: =IFERROR(SUM(C36:G36)/SUM(C$32:G$36),0) -> 0
B37: Total Profit | C37: =SUM(C32:C36) -> 0 | D37: =SUM(D32:D36) -> 0 | E37: =SUM(E32:E36) -> 0 | F37: =SUM(F32:F36) -> 0 | G37: =SUM(G32:G36) -> 0 | H37: =SUM(H32:H36) -> 0
B38: % | C38: =IFERROR(SUM(C32:C36)/SUM($C$32:$G$36),0) -> 0 | D38: =IFERROR(SUM(D32:D36)/SUM($C$32:$G$36),0) -> 0 | E38: =IFERROR(SUM(E32:E36)/SUM($C$32:$G$36),0) -> 0 | F38: =IFERROR(SUM(F32:F36)/SUM($C$32:$G$36),0) -> 0 | G38: =IFERROR(SUM(G32:G36)/SUM($C$32:$G$36),0) -> 0
B40: Total Profit % | H40: =IFERROR(H37/H10,0) -> 0

Sheet Next Steps ->

Sheet Strong and Fit KPIs
B1: Launch Goals
A2: Monthly Fit and Strong Sessions | B2: =SUM('Personal Training Proforma'!#REF!) -> #REF!
A3: Paid Trials Count Goal | B3: =(('Personal Training Proforma'!#REF!*'Personal Training Proforma'!#REF!)+('Personal Training Proforma'!#REF!*'Personal Training Proforma'!#REF!))/2 -> #REF!
A4: Launch TE to Long term PT % | B4: 0.2
A5: New Client Count | B5: =B4*B3 -> #REF!
A6: Session Per Week Per Member | B6: 2
A7: New Avg PT Month Package Value | B7: =AVERAGE('Personal Training Proforma'!#REF!)*(B6*4) -> #REF!
A8: Projected Draft Added | B8: =B5*B7 -> #REF!
B10: Month 1 | C10: Month 2 | D10: Month 3 | E10: Month 4 | F10: Month 5 | G10: Month 6
A11: Average Monthly New Members | B11: 20 | C11: 20 | D11: 20 | E11: 20 | F11: 20 | G11: 20
A12: FCs @ POS % | B12: 0.2 | C12: 0.2 | D12: 0.2 | E12: 0.2 | F12: 0.2 | G12: 0.2
A13: FC Booked at POS | B13: =B12*B11 -> 4 | C13: =C12*C11 -> 4 | D13: =D12*D11 -> 4 | E13: =E12*E11 -> 4 | F13: =F12*F11 -> 4 | G13: =G12*G11 -> 4
A14: Floor Pulls | B14: 2 | C14: 2 | D14: 2 | E14: 2 | F14: 2 | G14: 2
A15: FC Show % | B15: 0.5 | C15: 0.5 | D15: 0.5 | E15: 0.5 | F15: 0.5 | G15: 0.5
A16: FC Show | B16: =(B13+B14)*B15 -> 3 | C16: =(C13+C14)*C15 -> 3 | D16: =(D13+D14)*D15 -> 3 | E16: =(E13+E14)*E15 -> 3 | F16: =(F13+F14)*F15 -> 3 | G16: =(G13+G14)*G15 -> 3
A17: Long Term Agreement Close % | B17: 0.66 | C17: 0.66 | D17: 0.66 | E17: 0.66 | F17: 0.66 | G17: 0.66
A18: New Long Term PT Agreements | B18: =B16*B17 -> 1.98 | C18: =C16*C17 -> 1.98 | D18: =D16*D17 -> 1.98 | E18: =E16*E17 -> 1.98 | F18: =F16*F17 -> 1.98 | G18: =G16*G17 -> 1.98
A19: TE Agreement Close % | B19: 0.33 | C19: 0.33 | D19: 0.33 | E19: 0.33 | F19: 0.33 | G19: 0.33
A20: TE Agreement | B20: =B16*B19 -> 0.99 | C20: =C16*C19 -> 0.99 | D20: =D16*D19 -> 0.99 | E20: =E16*E19 -> 0.99 | F20: =F16*F19 -> 0.99 | G20: =G16*G19 -> 0.99
A21: Current TEs | B21: =B3 -> #REF! | C21: =B20 -> 0.99 | D21: =C20 -> 0.99 | E21: =D20 -> 0.99 | F21: =E20 -> 0.99 | G21: =F20 -> 0.99
A22: TE Closed to Long Term Agreement % | B22: =B4 -> 0.2 | C22: 1 | D22: 1 | E22: 1 | F22: 1 | G22: 1
A23: TE Closed to Long Term Agreement | B23: =B21*B22 -> #REF! | C23: =C21*C22 -> 0.99 | D23: =D21*D22 -> 0.99 | E23: =E21*E22 -> 0.99 | F23: =F21*F22 -> 0.99 | G23: =G21*G22 -> 0.99
A24: Projected Draft Added | B24: =(B18*$B$7)+(B23*$B$7) -> #REF! | C24: =(C18*$B$7)+(C23*$B$7) -> #REF! | D24: =(D18*$B$7)+(D23*$B$7) -> #REF! | E24: =(E18*$B$7)+(E23*$B$7) -> #REF! | F24: =(F18*$B$7)+(F23*$B$7) -> #REF! | G24: =(G18*$B$7)+(G23*$B$7) -> #REF!
A25: Total Draft | B25: =SUM($B$24:B24) -> #REF! | C25: =SUM($B$24:C24) -> #REF! | D25: =SUM($B$24:D24) -> #REF! | E25: =SUM($B$24:E24) -> #REF! | F25: =SUM($B$24:F24) -> #REF! | G25: =SUM($B$24:G24) -> #REF!
A26: % to revenue goal | B26: =B25/'Personal Training Proforma'!$J$7 -> #REF! | C26: =C25/'Personal Training Proforma'!$J$7 -> #REF! | D26: =D25/'Personal Training Proforma'!$J$7 -> #REF! | E26: =E25/'Personal Training Proforma'!$J$7 -> #REF! | F26: =F25/'Personal Training Proforma'!$J$7 -> #REF! | G26: =G25/'Personal Training Proforma'!$J$7 -> #REF!

Sheet Old ->

Sheet Personal Training Proforma
B1: Weekly Revenue | C1: 30 Min 1:1 | D1: 60 Min 1:1 | E1: Percussive Therapy 1:1 | F1: AF Strong | G1: AF HIIT | H1: GTR | J1: Monthly Total | L1: Annual Total
B2: PT Manager | C2: =Inputs!C$3*Inputs!C$6*Inputs!C10 -> 0 | D2: =Inputs!D$3*Inputs!D$6*Inputs!D10 -> 0 | E2: =Inputs!#REF!*Inputs!#REF!*Inputs!#REF! -> #REF! | F2: =Inputs!E$3*Inputs!E$6*Inputs!E10 -> 0 | G2: =Inputs!F$3*Inputs!F$6*Inputs!F10 -> 0 | H2: =Inputs!G$3*Inputs!G$6*Inputs!G10 -> 0 | J2: =SUM(C2:H2)*52/12 -> #REF! | L2: =SUM(C2:H2)*52 -> #REF!
B3: Coach 1 | C3: =Inputs!C$3*Inputs!C$6*Inputs!C11 -> 0 | D3: =Inputs!D$3*Inputs!D$6*Inputs!D11 -> 0 | E3: =Inputs!#REF!*Inputs!#REF!*Inputs!#REF! -> #REF! | F3: =Inputs!E$3*Inputs!E$6*Inputs!E11 -> 0 | G3: =Inputs!F$3*Inputs!F$6*Inputs!F11 -> 0 | H3: =Inputs!G$3*Inputs!G$6*Inputs!G11 -> 0 | J3: =SUM(C3:H3)*52/12 -> #REF! | L3: =SUM(C3:H3)*52 -> #REF!
B4: Coach 2 | C4: =Inputs!C$3*Inputs!C$6*Inputs!C12 -> 0 | D4: =Inputs!D$3*Inputs!D$6*Inputs!D12 -> 0 | E4: =Inputs!#REF!*Inputs!#REF!*Inputs!#REF! -> #REF! | F4: =Inputs!E$3*Inputs!E$6*Inputs!E12 -> 0 | G4: =Inputs!F$3*Inputs!F$6*Inputs!F12 -> 0 | H4: =Inputs!G$3*Inputs!G$6*Inputs!G12 -> 0 | J4: =SUM(C4:H4)*52/12 -> #REF! | L4: =SUM(C4:H4)*52 -> #REF!
B5: Coach 3 | C5: =Inputs!C$3*Inputs!C$6*Inputs!C13 -> 0 | D5: =Inputs!D$3*Inputs!D$6*Inputs!D13 -> 0 | E5: =Inputs!#REF!*Inputs!#REF!*Inputs!#REF! -> #REF! | F5: =Inputs!E$3*Inputs!E$6*Inputs!E13 -> 0 | G5: =Inputs!F$3*Inputs!F$6*Inputs!F13 -> 0 | H5: =Inputs!G$3*Inputs!G$6*Inputs!G13 -> 0 | J5: =SUM(C5:H5)*52/12 -> #REF! | L5: =SUM(C5:H5)*52 -> #REF!
B6: Coach 4 | C6: =Inputs!C$3*Inputs!C$6*Inputs!C14 -> 0 | D6: =Inputs!D$3*Inputs!D$6*Inputs!D14 -> 0 | E6: =Inputs!#REF!*Inputs!#REF!*Inputs!#REF! -> #REF! | F6: =Inputs!E$3*Inputs!E$6*Inputs!E14 -> 0 | G6: =Inputs!F$3*Inputs!F$6*Inputs!F14 -> 0 | H6: =Inputs!G$3*Inputs!G$6*Inputs!G14 -> 0 | J6: =SUM(C6:H6)*52/12 -> #REF! | L6: =SUM(C6:H6)*52 -> #REF!
B7: Total Revenue | C7: =SUM(C2:C6) -> 0 | D7: =SUM(D2:D6) -> 0 | E7: =SUM(E2:E6) -> #REF! | F7: =SUM(F2:F6) -> 0 | G7: =SUM(G2:G6) -> 0 | H7: =SUM(H2:H6) -> 0 | J7: =SUM(C7:H7)*52/12 -> #REF! | L7: =SUM(C7:H7)*52 -> #REF!
B8: % of Total Revenue | C8: =SUM(C2:C7)/SUM($C$2:$H$7) -> #REF! | D8: =SUM(D2:D7)/SUM($C$2:$H$7) -> #REF! | E8: =SUM(E2:E7)/SUM($C$2:$H$7) -> #REF! | F8: =SUM(F2:F7)/SUM($C$2:$H$7) -> #REF! | G8: =SUM(G2:G7)/SUM($C$2:$H$7) -> #REF! | H8: =SUM(H2:H7)/SUM($C$2:$H$7) -> #REF!
B10: COGS Monthly Hours | C10: 30 Min 1:1 | D10: 60 Min 1:1 | F10: AF Strong | G10: AF HIIT
B11: Base Salary | C11: 10
B12: PT Manager
B13: Coach 1
B14: Coach 2
B15: Coach 3
B16: Coach 4
B18: COGS Hourly Rate | C18: 30 Min 1:1 | D18: 60 Min 1:1 | F18: AF Strong | G18: AF HIIT
B19: Base Salary | C19: 20
B20: PT Manager
B21: Coach 1
B22: Coach 2
B23: Coach 3
B24: Coach 4
B28: COGS | C28: Monthly Hours | F28: Hourly Rate
B29: Base Salary | C29: =C11*C19 -> 200
B30: PT Manager | J30: =C30*F30 -> 0 | L30: =J30/4*52 -> 0
B31: Coach 1 | J31: =C31*F31 -> 0 | L31: =J31/4*52 -> 0
B32: Coach 2 | J32: =C32*F32 -> 0 | L32: =J32/4*52 -> 0
B33: Coach 3 | J33: =C33*F33 -> 0 | L33: =J33/4*52 -> 0
B34: Coach 4 | J34: =C34*F34 -> 0 | L34: =J34/4*52 -> 0
B37: Weekly COGS | C37: 30 Min 1:1 | D37: 60 Min 1:1 | E37: Percussive Therapy 1:1 | F37: AF Strong | G37: AF HIIT | H37: GTR
B38: PT Manager | C38: =Inputs!C$7*Inputs!C10*Inputs!$C25 -> 0 | D38: =Inputs!D$7*Inputs!D10*Inputs!$C25 -> 0 | E38: =Inputs!#REF!*Inputs!#REF!*Inputs!$C25 -> #REF! | F38: =Inputs!E$7*Inputs!E10*Inputs!$C25 -> 0 | G38: =Inputs!F$7*Inputs!F10*Inputs!$C25 -> 0 | H38: =Inputs!G$7*Inputs!G10*Inputs!$C25 -> 0
B39: Coach 1 | C39: =Inputs!C$7*Inputs!C11*Inputs!$C26 -> 0 | D39: =Inputs!D$7*Inputs!D11*Inputs!$C26 -> 0 | E39: =Inputs!#REF!*Inputs!#REF!*Inputs!$C26 -> #REF! | F39: =Inputs!E$7*Inputs!E11*Inputs!$C26 -> 0 | G39: =Inputs!F$7*Inputs!F11*Inputs!$C26 -> 0 | H39: =Inputs!G$7*Inputs!G11*Inputs!$C26 -> 0
B40: Coach 2 | C40: =Inputs!C$7*Inputs!C12*Inputs!$C27 -> 0 | D40: =Inputs!D$7*Inputs!D12*Inputs!$C27 -> 0 | E40: =Inputs!#REF!*Inputs!#REF!*Inputs!$C27 -> #REF! | F40: =Inputs!E$7*Inputs!E12*Inputs!$C27 -> 0 | G40: =Inputs!F$7*Inputs!F12*Inputs!$C27 -> 0 | H40: =Inputs!G$7*Inputs!G12*Inputs!$C27 -> 0
B41: Coach 3 | C41: =Inputs!C$7*Inputs!C13*Inputs!$C28 -> 0 | D41: =Inputs!D$7*Inputs!D13*Inputs!$C28 -> 0 | E41: =Inputs!#REF!*Inputs!#REF!*Inputs!$C28 -> #REF! | F41: =Inputs!E$7*Inputs!E13*Inputs!$C28 -> 0 | G41: =Inputs!F$7*Inputs!F13*Inputs!$C28 -> 0 | H41: =Inputs!G$7*Inputs!G13*Inputs!$C28 -> 0
B42: Coach 4 | C42: =Inputs!C$7*Inputs!C14*Inputs!$C29 -> 0 | D42: =Inputs!D$7*Inputs!D14*Inputs!$C29 -> 0 | E42: =Inputs!#REF!*Inputs!#REF!*Inputs!$C29 -> #REF! | F42: =Inputs!E$7*Inputs!E14*Inputs!$C29 -> 0 | G42: =Inputs!F$7*Inputs!F14*Inputs!$C29 -> 0 | H42: =Inputs!G$7*Inputs!G14*Inputs!$C29 -> 0
B44: COGS % of Session Value
B45: PT Manager
B46: Coach 1
B47: Coach 2
B48: Coach 3
...
