Workbook
Name RENT: Input!$C$18

Sheet Macro1

Sheet Input
A1: ENTER MONTHLY EXPENSE AMOUNTS BELOW BASED ON CURRENT PROFIT AND LOSS DATA PROVIDED BY THE SELLER OF THE CLUB
A4: Operating Expenses
A5: Payroll Expenses | C5: =SUM(C6:C9) -> 0
B6: Payroll
B7: Payroll - Taxes
B8: Payroll - Benefits
B9: Travel & Entertainment
A10: Franchise Expenses | C10: =SUM(C11:C13) -> 0
B11: Royalty Payments
B12: Software Support
B13: General Ad Fund | D13: **$600 max per 2019 FDD
A14: Advertising/Marketing | C14: =SUM(C15:C16) -> 0
B15: Advertising/Marketing
B16: Postage
A17: Property Expenses | C17: =SUM(C18:C22) -> 0
B18: Rent
B19: Taxes - Property
B20: Utilities (Trash/Water/Electric/Gas)
B21: Telephone
B22: Internet/Cable
A23: Professional Expenses | C23: =SUM(C24:C25) -> 0
B24: Insurance
B25: Legal & Accounting
A26: Misc Expenses | C26: =SUM(C27:C36) -> 0
B27: Bank Fees
B28: Credit Card Fees
B29: Dues and Subscriptions
B30: Equipment Expense
B31: Office Supplies
B32: Repairs & Maint
B33: <Enter>
B34: <Enter>
B35: <Enter>
B36: <Enter>
C37: =C5+C10+C14+C17+C23+C26 -> 0

Sheet AF Projections
A1: Anytime Fitness Full Size Unit Pro Forma Calculator **Please See Footnotes Below Prior to Starting Exercise**
A2: This calculator is provided in blank to prospective franchisees of Anytime Fitness. All revenues and expense assumptions must be completed by prospective franchisees.
A5: Membership Data Assumptions
A6: % of PPV Accounts
A7: Acquired PPV Accounts
A8: Acquired Single Members
A9: Enrollment fee
A10: Average Member Fee
A11: Average PPV Fee
A13: Attrition Rate
A16: Other Income Assumptions
A17: Personal Training Income/Member
... A28: Expense Assumptions (ENTER IN INPUT TAB)
A29: Rent | B29: =RENT -> 0
A30: Monthly Franchise Fee | B30: =Input!C11 -> 0
A31: Base Technology Fee | B31: =Input!C12 -> 0
A32: General Advertising Fee | B32: =Input!C13 -> 0
A33: Advertising (Local) | B33: =Input!C14 -> 0
A34: Payroll | B34: =Input!C5 -> 0
A35: Utilities | B35: =SUM(Input!C20:C22) -> 0
A36: Property Taxes | B36: =Input!C19 -> 0
A37: Insurance | B37: =Input!C24 -> 0
A38: Professional Fees | B38: =Input!C25 -> 0
A39: Bank/CC Fees | B39: =Input!C27+Input!C28 -> 0
A40: Supplies | B40: =Input!C29+Input!C30+Input!C31 -> 0
A41: Maintenace | B41: =Input!C32 -> 0
A42: Miscellaneous | B42: =SUM(Input!C33:C36) -> 0
A43: Bad Debt Percentage
A46: # of months Rent Abatement
A49: NOTE: All information contained in this document is for example only. Revenue and expense figures may vary significantly based on numerous factors.
A51: YEAR 1 | B51: Beginning Balance | C51: Month 1 | D51: Month2 | E51: Month3 | F51: Month 4 | G51: Month 5 | H51: Month 6 | I51: Month 7 | J51: Month 8 | K51: Month 9 | L51: Month 10 | M51: Month 11 | N51: Month 12
A52: Monthly New Members
A53: (6) Single Members | B53: 0 | C53: =ROUND((C52*(1-$B$6)),0) -> 0 | D53: =ROUND((D52*(1-$B$6)),0) -> 0 | E53: =ROUND((E52*(1-$B$6)),0) -> 0 | F53: =ROUND((F52*(1-$B$6)),0) -> 0 | G53: =ROUND((G52*(1-$B$6)),0) -> 0 | H53: =ROUND((H52*(1-$B$6)),0) -> 0 | I53: =ROUND((I52*(1-$B$6)),0) -> 0 | J53: =ROUND((J52*(1-$B$6)),0) -> 0 | ... N53: =ROUND((N52*(1-$B$6)),0) -> 0
A54: Member Attrition | B54: 0 | C54: =-B55*($B$13/12) -> 0 | D54: =-C55*($B$13/12) -> 0 | E54: =-D55*($B$13/12) -> 0 | F54: =-E55*($B$13/12) -> 0 | G54: =-F55*($B$13/12) -> 0 | H54: =-G55*($B$13/12) -> 0 | I54: =-H55*($B$13/12) -> 0 | J54: =-I55*($B$13/12) -> 0 | ... N54: =-M55*($B$13/12) -> 0
A55: Accumulated Single Members | B55: =B8 -> 0 | C55: =B55+C53+C54 -> 0 | D55: =C55+D53+D54 -> 0 | E55: =D55+E53+E54 -> 0 | F55: =E55+F53+F54 -> 0 | G55: =F55+G53+G54 -> 0 | H55: =G55+H53+H54 -> 0 | I55: =H55+I53+I54 -> 0 | J55: =I55+J53+J54 -> 0 | ... N55: =M55+N53+N54 -> 0
A56: Pay Per Visit "PPV" Members | B56: 0 | C56: =ROUND(C52*$B$6,0) -> 0 | D56: =ROUND(D52*$B$6,0) -> 0 | E56: =ROUND(E52*$B$6,0) -> 0 | F56: =ROUND(F52*$B$6,0) -> 0 | G56: =ROUND(G52*$B$6,0) -> 0 | H56: =ROUND(H52*$B$6,0) -> 0 | I56: =ROUND(I52*$B$6,0) -> 0 | J56: =ROUND(J52*$B$6,0) -> 0 | ... N56: =ROUND(N52*$B$6,0) -> 0
A57: PPV Attrition | B57: 0 | C57: =-B58*($B$13/12) -> 0 | D57: =-C58*($B$13/12) -> 0 | E57: =-D58*($B$13/12) -> 0 | F57: =-E58*($B$13/12) -> 0 | G57: =-F58*($B$13/12) -> 0 | H57: =-G58*($B$13/12) -> 0 | I57: =-H58*($B$13/12) -> 0 | J57: =-I58*($B$13/12) -> 0 | ... N57: =-M58*($B$13/12) -> 0
A58: Accumulated PPV Members | B58: =B7 -> 0 | C58: =B58+C56+C57 -> 0 | D58: =C58+D56+D57 -> 0 | E58: =D58+E56+E57 -> 0 | F58: =E58+F56+F57 -> 0 | G58: =F58+G56+G57 -> 0 | H58: =G58+H56+H57 -> 0 | I58: =H58+I56+I57 -> 0 | J58: =I58+J56+J57 -> 0 | ... N58: =M58+N56+N57 -> 0
A59: Accumulating Total Members | B59: =B55+B58 -> 0 | C59: =C58+C55 -> 0 | D59: =D58+D55 -> 0 | E59: =E58+E55 -> 0 | F59: =F58+F55 -> 0 | G59: =G58+G55 -> 0 | H59: =H58+H55 -> 0 | I59: =I58+I55 -> 0 | J59: =J58+J55 -> 0 | ... N59: =N58+N55 -> 0
A60: Recur Single Memb Rev | C60: =C55*$B$10 -> 0 | D60: =D55*$B$10 -> 0 | E60: =E55*$B$10 -> 0 | F60: =F55*$B$10 -> 0 | G60: =G55*$B$10 -> 0 | H60: =H55*$B$10 -> 0 | I60: =I55*$B$10 -> 0 | J60: =J55*$B$10 -> 0 | ... N60: =N55*$B$10 -> 0
...
