Workbook

Sheet Goals,Tracking & ROAS
B8: MARKETING GOAL SETTING, TRACKING & CALCULATING ROAS
B11: TABLE 1 | C11: Set Your Goal | I11: TABLE 2 | J11: Key Inputs | Q11: TABLE 3 | R11: Planned Marketing Tactics to Drive Leads | V11: TABLE 4 | W11: Calculate Return on Ad Spend (ROAS)
B12: Set your Goal | C12: Recommended goals listed below | I12: Enter Key Inputs | J12: 1. NEW member goal | N12: =G13 -> 0 | O12: =DAY(EOMONTH(#REF!,0)) -> #REF! | Q12: Plan How You Will Get Your Leads | R12: Marketing Tactics | S12: Lead Goal | T12: Actual Leads | V12: Determine the return on ad spend of your marketing activities | W12: 1: Club Lifetime Value (LTV) | X12: Member Lifetime Value
C13: New member goal | G13: 0 | J13: 2. Average lead to member conversion rate
J14: 3. Total leads needed | N14: =N12/N13 -> #DIV/0! | R14: 1. Digital Paid Media channels (search & social) | W14: 2: Marketing Budget *Not including agency fees | X14: Marketing Budget
R16: 2. Traditional Paid Media tactics | W16: 3: Total leads | X16: Total leads driven from marketing tactics | Z16: =T22 -> 0
R18: 3. B2B Partnerships | W18: 4: Determine Cost Per Lead (CPL) | X18: (total budget/total leads) | Z18: =Z14/Z16 -> #DIV/0!
R20: 4. Community Events | W20: 5: Club conversion rate | X20: Lead to member conversion rate | Z20: =N13 -> 0
B22: COLOR CODE KEY | R22: Total Leads | S22: =SUM(S14:S23) -> 0 | T22: =SUM(T14:T23) -> 0 | W22: 6: Calculate leads converted to members | X22: (Total Leads X Rate of Close = Total New Members) | Z22: =Z16*Z20 -> 0
B23: Owner/Manager to add Goal Info
W24: 7: Revenue Driven | X24: (New Members X LTV = Money Generated) | Z24: =Z22*Z12 -> 0
B25: Pull Club Data from Club OS
B26: Auto populates | W26: 8: Calculate Return on Ad Spend (ROAS) | X26: (Amount Gained - Amount Spent) / Amount Spent | Z26: =(Z24-Z14)/Z14 -> #DIV/0!
B29: KEY TERMS | I29: TABLE 2 INSTRUCTIONS | Q29: TABLE 3 INSTRUCTIONS | V29: TABLE 4 INSTRUCTIONS
B30: Cost Per Lead (CPL): The amount of money you pay for a lead to come to your club. To calculate your CPL, take your total budget and divide it by your total leads (Total Budget/Total Leads). Lifetime Value (LTV): The total amount a member will give your club over the tenure of their contract. Return on Ad Spend (ROAS): Total revenue for every dollar spent on marketing. *This dollar amount does not include paid media partner management fees | I30: 1. Set your new member goal 2 . Find your club's average lead to member conversion rate by going to: Club OS > Dashboard > Sales Performance > New Leads and using the following filters: Location: Your Clubs Employee: All Marketing Source: All User Origin: All Date Rage: Custom (We recommend choosing 1 month during a similar time frame) 3. Total leads needed to meet member goal will auto populate | Q30: **Before you fill out Table 3 complete the "Plan on a Page" tab to determine your marketing tactics** 1. In column "S", enter calculated digital paid media lead goal (paid media budget divided by club's digital paid media CPL, which can be found on your agency dashboard. AF's steady state digital paid CPL goal is $35 (combined search and social) EXAMPLE: (investment) $1,000 / (CPL) $35 = 28.5 (potential digital paid media leads) 2. In column "S", enter traditional paid media lead goal based on club's previous performance 3. In column "S", enter business partnership lead goal based on club's previous performance 4. In column "S", enter Community event lead goal based on club's previous performance or 10% of people you interact with at event Total Lead Goal Auto Populates **End of month enter actual leads in column "T"** Find your club's New Lead actuals per channel by going to: Club OS > Dashboard > Sales Performance > New Leads by Source (example: Web, Walk-in, App, Phone, Ads, Facebook, Referral) Total Actual Leads Auto Populates *If total actual leads meets or exceed your lead goal in "Table 2" the cell will turn green, if it is below the goal it will turn red | V30: 1. Determine club Lifetime value (LTV) Calculate LTV = monthly member dues X average length of member tenure. Average member tenure is 16 - 18 months (example: $50 X 18 = $900) 2. Enter monthly marketing budget as filled out in "Plan on a Page" *This total does not include agency fees 3. Auto populates Total Actual Leads when "Table 3" is completely filled out *If total actual leads meets or exceed your lead goal in "Table 2" the cell will turn green, if it is below the goal it will turn red 4. Auto populates Marketing campaign Cost Per Lead (CPL) by dividing the total marketing budget by the actual total leads 5. Auto populates member conversion rate as completed in "Table 2" 6. Auto populates leads converted to members (total actual leads multiplied by lead to member conversion rate) 7. Auto populates revenue driven from new members (new member total as populated above multiplied by Lifetime Value) 8. Auto populates the Return on Ad Spend (ROAS) for marketing campaign (total revenue minus marketing spend, divided by marketing spend = ROAS) $3 or higher is a good return on ad spend *if your ROAS meets or exceeds $3 the cell will turn green, if below it will turn red
I32: Example club dashboard - Woodbury, MN

Sheet Q1 - Plan on a Page 
G2: Marketing Budget Spend Requirements
G3: FDD Requirement: Invest monthly spend investment (based on population) in local marketing tactics. *Recommended increase budget in Search and Social tactics during local promotions
E5: COLOR CODE KEY | G5: Based on Population Density 3-mile radius | I5: FDD Minimum Spend Requirement | K5: Recommended Budget* (during local promotions)
E6: Owner/Manager to add Info | G6: Tier 1 / Urban (50,000<) | I6: $1,000 / month ($12,000 annually) | K6: $1,500 / month (per channel)
B7: LOCAL MARKETING PLAN ON A PAGE | E7: Auto populates | G7: Tier 2 / Suburban (25,000 - 49,999) | I7: $800 / month ($9,600 annually) | K7: $1,000 per / month (per channel)
G8: Tier 3 / Rural (<25,000) | I8: $600 / month ($7,200 annually) | K8: $500 / month (per channel)
B10: STEP 1: Review the Corporate Marketing Calendar and Local Marketing Recommendations
E11: Q1
E12: JAN | G12: FEB | I12: MAR
B13: Corporate Marketing (GAF Investment)
B14: Corporate Campaigns *Increased paid media investment during these times | D14: Increase awareness and consideration | E14: January Campaign (Join for $1 + TC)
B15: Steady State | D15: Maintain awareness and consideration | G15: Increased investment in Steady State Paid Media
B17: Local Marketing *recommended timing of local promotions
B18: Local Club - Member Acquisition offer *Increase paid media investment during these times | D18: Bring in new members | E18: January Local Offer (Join for $1 + TC Free) | G18: Steady state - 7 day pass | I18: Spring Local Offer - Join for $1
B19: Local Club - PT Conversion Offer *Internal promotion to existing member - no paid media | D19: Drive new PT sign-ups | G19: PT Offer
B21: STEP 2: Plan your Local Marketing promotions, tactics and budget
B22: Local Marketing Planning Calendar (Fill in your local marketing tactics & budget) | D22: Notes/Examples | E22: JAN | G22: FEB | I22: MAR
B23: Paid Media - (Digital) Fill in monthly Paid Media plan & budget | D23: Paid media agency (Paid search & social) | E23: EXAMPLE: Increased to recommended spend for Jan Campaign, with Keepbooked | F23: 2000 | H23: {='Q1 - Plan on a Page '!H23:H28} -> 0 | I23: {='Yearly Plan on a Page'!I23:I28} -> 0 | J23: 0
B24: Paid Media - (Tradional) Fill in monthly Paid Media plan & budget | D24: Posters, Sidewalk Signs, Flyers, Direct Mailers, Door hangers, etc. | E24: EXAMPLE: Distributed direct mailers to local neighborhoods | F24: 200 | H24: 0 | J24: 0
B25: Community Marketing - B2B Partnerships Fill in monthly B2B Partnership plan & budget | D25: Plan ahead to order print assets and branded swag (flyers, business cards etc.) | E25: EXAMPLE: Doorhangers for Carwash partnership (hang in rearview mirrors) | F25: 100 | H25: 0 | J25: 0
B26: Community Marketing - Community Events #1 Fill in monthly Community Event plan & budget | D26: Plan ahead to order print assets and branded swag (price presentation sheets, swag, yard signs, banners, business cards, etc.) | E26: EXAMPLE: Sponsor local sports team & table at game | F26: 100 | H26: 0 | J26: 0
B27: Community Marketing - Community Events #2 Fill in monthly Community Event plan & budget | E27: EXAMPLE: Host AF WorkOut | F27: 50 | H27: 0 | J27: 0
B28: Community Marketing - Community Events #3 Fill in monthly Community Event plan & budget | E28: EXAMPLE: Donation Center Dropoff | F28: 50 | H28: 0 | J28: 0
B29: TOTAL | F29: =SUM(F23:F28) -> 2500 | H29: =SUM(H23:H28) -> 0 | J29: =SUM(J23:J28) -> 0

Sheet Q2 - Plan on a Page
G2: Marketing Budget Spend Requirements
G3: FDD Requirement: Invest monthly spend investment (based on population) in local marketing tactics. *Recommended increase budget in Search and Social tactics during local promotions
E5: COLOR CODE KEY | G5: Based on Population Density 3-mile radius | I5: FDD Minimum Spend Requirement | K5: Recommended Budget* (during local promotions)
E6: Owner/Manager to add Info | G6: Tier 1 / Urban (50,000<) | I6: $1,000 / month ($12,000 annually) | K6: $1,500 / month (per channel)
B7: LOCAL MARKETING PLAN ON A PAGE | E7: Auto populates | G7: Tier 2 / Suburban (25,000 - 49,999) | I7: $800 / month ($9,600 annually) | K7: $1,000 per / month (per channel)
G8: Tier 3 / Rural (<25,000) | I8: $600 / month ($7,200 annually) | K8: $500 / month (per channel)
B10: STEP 1: Review the Corporate Marketing Calendar and Local Marketing Recommendations
E11: Q2
E12: APR | G12: MAY | I12: JUN
B13: Corporate Marketing (GAF Investment)
B14: Corporate Campaigns *Increased paid media investment during these times | D14: Increase awareness and consideration | G14: Summer campaign - Join and Get 2 Months Free
B15: Steady State | D15: Maintain awareness and consideration | E15: Increased investment in Steady State Paid Media | I15: Increased investment in Steady State Paid Media
B17: Local Marketing *recommended timing of local promotions
B18: Local Club - Member Acquisition offer *Increase paid media investment during these times | D18: Bring in new members | E18: Steady state - 7 day pass | G18: Summer campaign - Join and Get 2 Months Free | I18: Steady state - 7 day pass
B19: Local Club - PT Conversion Offer *Internal promotion to existing member - no paid media | D19: Drive new PT sign-ups | E19: PT Offer | I19: PT Offer
B21: STEP 2: Plan your Local Marketing promotions, tactics and budget
B22: Local Marketing Planning Calendar (Fill in your local marketing tactics & budget) | D22: Notes/Examples | E22: APR | G22: MAY | I22: JUN
B23: Paid Media - (Digital) Fill in monthly Paid Media plan & budget | D23: Paid media agency (Paid search & social) | F23: 0 | H23: 0 | J23: 0
B24: Paid Media - (Tradional) Fill in monthly Paid Media plan & budget | D24: Posters, Sidewalk Signs, Flyers, Direct Mailers, Door hangers, etc. | F24: 0 | H24: 0 | J24: 0
B25: Community Marketing - B2B Partnerships Fill in monthly B2B Partnership plan & budget | D25: Plan ahead to order print assets and branded swag (flyers, business cards etc.) | F25: 0 | H25: 0 | J25: 0
B26: Community Marketing - Community Events #1 Fill in monthly Community Event plan & budget | D26: Plan ahead to order print assets and branded swag (price presentation sheets, swag, yard signs, banners, business cards, etc.) | F26: 0 | H26: 0 | J26: 0
B27: Community Marketing - Community Events #2 Fill in monthly Community Event plan & budget | F27: 0 | H27: 0 | J27: 0
B28: Community Marketing - Community Events #3 Fill in monthly Community Event plan & budget | F28: 0 | H28: 0 | J28: 0
B29: TOTAL | F29: =SUM(F23:F28) -> 0 | H29: =SUM(H23:H28) -> 0 | J29: =SUM(J23:J28) -> 0

Sheet Q3 - Plan on a Page
G2: Marketing Budget Spend Requirements
G3: FDD Requirement: Invest monthly spend investment (based on population) in local marketing tactics. *Recommended increase budget in Search and Social tactics during local promotions
E5: COLOR CODE KEY | G5: Based on Population Density 3-mile radius | I5: FDD Minimum Spend Requirement | K5: Recommended Budget* (during local promotions)
E6: Club to fill out | G6: Tier 1 / Urban (50,000<) | I6: $1,000 / month ($12,000 annually) | K6: $1,500 / month (per channel)
B7: LOCAL MARKETING PLAN ON A PAGE | E7: Auto populates | G7: Tier 2 / Suburban (25,000 - 49,999) | I7: $800 / month ($9,600 annually) | K7: $1,000 per / month (per channel)
G8: Tier 3 / Rural (<25,000) | I8: $600 / month ($7,200 annually) | K8: $500 / month (per channel)
B10: STEP 1: Review the Corporate Marketing Calendar and Local Marketing Recommendations
E11: Q3
E12: JUL | G12: AUG | I12: SEPT
B13: Corporate Marketing (GAF Investment)
B14: Corporate Campaigns *Increased paid media investment during these times | D14: Increase awareness and consideration
B15: Steady State | D15: Maintain awareness and consideration | E15: Increased investment in Steady State Paid Media
B17: Local Marketing *recommended timing of local promotions
B18: Local Club - Member Acquisition offer *Increase paid media investment during these times | D18: Bring in new members | E18: Steady state - 7 day pass | I18: Fall Local Offer
B19: Local Club - PT Conversion Offer *Internal promotion to existing member - no paid media | D19: Drive new PT sign-ups
B21: STEP 2: Plan your Local Marketing promotions, tactics and budget
B22: Local Marketing Planning Calendar (Fill in your local marketing tactics & budget) | D22: Notes/Examples | E22: JUL | G22: AUG | I22: SEPT
B23: Paid Media - (Digital) Fill in monthly Paid Media plan & budget | D23: Paid media agency (Paid search & social) | F23: 0 | H23: 0 | J23: 0
B24: Paid Media - (Tradional) Fill in monthly Paid Media plan & budget | D24: Posters, Sidewalk Signs, Flyers, Direct Mailers, Door hangers, etc. | F24: 0 | H24: 0 | J24: 0
B25: Community Marketing - B2B Partnerships Fill in monthly B2B Partnership plan & budget | D25: Plan ahead to order print assets and branded swag (flyers, business cards etc.) | F25: 0 | H25: 0 | J25: 0
B26: Community Marketing - Community Events #1 Fill in monthly Community Event plan & budget | D26: Plan ahead to order print assets and branded swag (price presentation sheets, swag, yard signs, banners, business cards, etc.) | F26: 0 | H26: 0 | J26: 0
B27: Community Marketing - Community Events #2 Fill in monthly Community Event plan & budget | F27: 0 | H27: 0 | J27: 0
B28: Community Marketing - Community Events #3 Fill in monthly Community Event plan & budget | F28: 0 | H28: 0 | J28: 0
B29: TOTAL | F29: =SUM(F23:F28) -> 0 | H29: =SUM(H23:H28) -> 0 | J29: =SUM(J23:J28) -> 0

Sheet Q4 - Plan on a Page
G2: Marketing Budget Spend Requirements
G3: FDD Requirement: Invest monthly spend investment (based on population) in local marketing tactics. *Recommended increase budget in Search and Social tactics during local promotions
E5: COLOR CODE KEY | G5: Based on Population Density 3-mile radius | I5: FDD Minimum Spend Requirement | K5: Recommended Budget* (during local promotions)
E6: Club to fill out | G6: Tier 1 / Urban (50,000<) | I6: $1,000 / month ($12,000 annually) | K6: $1,500 / month (per channel)
B7: LOCAL MARKETING PLAN ON A PAGE | E7: Auto populates | G7: Tier 2 / Suburban (25,000 - 49,999) | I7: $800 / month ($9,600 annually) | K7: $1,000 per / month (per channel)
G8: Tier 3 / Rural (<25,000) | I8: $600 / month ($7,200 annually) | K8: $500 / month (per channel)
B10: STEP 1: Review the Corporate Marketing Calendar and Local Marketing Recommendations
E11: Q4
E12: OCT | G12: NOV | I12: DEC
B13: Corporate Marketing (GAF Investment)
B14: Corporate Campaigns *Increased paid media investment during these times | D14: Increase awareness and consideration | H14: Black Friday Campaign - Join and get rest of Year Free | I14: January Campaign begins
B15: Steady State | D15: Maintain awareness and consideration | E15: Increased investment in Steady State Paid Media
B17: Local Marketing *recommended timing of local promotions
B18: Local Club - Member Acquisition offer *Increase paid media investment during these times | D18: Bring in new members | E18: Steady state - 7 day pass | G18: Black Friday - Join and Get Rest of Year Free | I18: Steady state - 7 day pass
B19: Local Club - PT Conversion Offer *Internal promotion to existing member - no paid media | D19: Drive new PT sign-ups | E19: PT Offer | I19: PT Offer
B21: STEP 2: Plan your Local Marketing promotions, tactics and budget
B22: Local Marketing Planning Calendar (Fill in your local marketing tactics & budget) | D22: Notes/Examples | E22: OCT | G22: NOV | I22: DEC
B23: Paid Media - (Digital) Fill in monthly Paid Media plan & budget | D23: Paid media agency (Paid search & social) | F23: 0 | H23: 0 | J23: 0
B24: Paid Media - (Tradional) Fill in monthly Paid Media plan & budget | D24: Posters, Sidewalk Signs, Flyers, Direct Mailers, Door hangers, etc. | F24: 0 | H24: 0 | J24: 0
B25: Community Marketing - B2B Partnerships Fill in monthly B2B Partnership plan & budget | D25: Plan ahead to order print assets and branded swag (flyers, business cards etc.) | F25: 0 | H25: 0 | J25: 0
B26: Community Marketing - Community Events #1 Fill in monthly Community Event plan & budget | D26: Plan ahead to order print assets and branded swag (price presentation sheets, swag, yard signs, banners, business cards, etc.) | F26: 0 | H26: 0 | J26: 0
B27: Community Marketing - Community Events #2 Fill in monthly Community Event plan & budget | F27: 0 | H27: 0 | J27: 0
B28: Community Marketing - Community Events #3 Fill in monthly Community Event plan & budget | F28: 0 | H28: 0 | J28: 0
B29: TOTAL | F29: =SUM(F23:F28) -> 0 | H29: =SUM(H23:H28) -> 0 | J29: =SUM(J23:J28) -> 0

Sheet Yearly Plan on a Page
G2: Marketing Budget Spend Requirements
G3: FDD Requirement: Invest monthly spend investment (based on population) in local marketing tactics. *Recommended increase budget in Search and Social tactics during local promotions
E5: COLOR CODE KEY | G5: Based on Population Density 3-mile radius | I5: FDD Minimum Spend Requirement | K5: Recommended Budget* (during local promotions)
E6: Owner/Manager to add Info | G6: Tier 1 / Urban (50,000<) | I6: $1,000 / month ($12,000 annually) | K6: $1,500 / month (per channel)
B7: LOCAL MARKETING PLAN ON A PAGE | E7: Auto populates | G7: Tier 2 / Suburban (25,000 - 49,999) | I7: $800 / month ($9,600 annually) | K7: $1,000 per / month (per channel)
G8: Tier 3 / Rural (<25,000) | I8: $600 / month ($7,200 annually) | K8: $500 / month (per channel)
B10: STEP 1: Review the Corporate Marketing Calendar and Local Marketing Recommendations
E11: Q1 | K11: Q2 | Q11: Q3 | W11: Q4
E12: JAN | G12: FEB | I12: MAR | K12: APR | M12: MAY | O12: JUN | Q12: JUL | S12: AUG | U12: SEPT | W12: OCT | Y12: NOV | AA12: DEC
B13: Corporate Marketing (GAF Investment)
B14: Corporate Campaigns *Increased paid media investment during these times | D14: Increase awareness and consideration | E14: January Campaign (Join for $1 + TC Free) | M14: Summer campaign - Join and Get 2 Months Free | Z14: Black Friday Campaign - Join and get rest of Year | AA14: January Campaign begins
B15: Steady State | D15: Maintain awareness and consideration | G15: Increased investment in Steady State Paid Media | O15: Increased investment in Steady State Paid Media
B17: Local Marketing *recommended timing of local promotions
B18: Local Club - Member Acquisition offer *Increase paid media investment during these times | D18: Bring in new members | E18: January Local Offer (Join for $1 + TC Free) | G18: Steady state - 7 day pass | I18: Spring Local Offer - Join for $1 | K18: Steady state - 7 day pass | M18: Summer campaign - Join and Get 2 Months Free | O18: Steady state - 7 day pass | U18: Fall Local Offer | W18: Steady state - 7 day pass | Y18: Black Friday - Join and Get Rest of Year Free
B19: Local Club - PT Conversion Offer *Internal promotion to existing member - no paid media | D19: Drive new PT sign-ups | G19: PT Offer | K19: PT Offer | O19: PT Offer | W19: PT Offer | AA19: PT Offer
B21: STEP 2: Plan your Local Marketing promotions, tactics and budget
B22: Local Marketing Planning Calendar (Fill in your local marketing tactics & budget) | D22: Notes/Examples | E22: JAN | G22: FEB | I22: MAR | K22: APR | M22: MAY | O22: JUN | Q22: JUL | S22: AUG | U22: SEPT | W22: OCT | Y22: NOV | AA22: DEC
B23: Paid Media - (Digital) Fill in monthly Paid Media plan & budget | D23: Paid media agency (Paid search & social) | E23: ='Q1 - Plan on a Page '!E23 -> EXAMPLE: Increased to recommended spend for Jan Campaign, with Keepbooked | F23: ='Q1 - Plan on a Page '!F23 -> 2000 | G23: {='Q1 - Plan on a Page '!G23:G28} -> 0 | H23: {='Q1 - Plan on a Page '!H23:H28} -> 0 | I23: {='Q1 - Plan on a Page '!I23:I28} -> 0 | J23: {='Q1 - Plan on a Page '!J23:J28} -> 0 | K23: {='Q2 - Plan on a Page'!E23:E28} -> 0 | L23: ='Q2 - Plan on a Page'!F23 -> 0 | M23: {='Q2 - Plan on a Page'!G23:G28} -> 0 | N23: ='Q2 - Plan on a Page'!H23 -> 0 | O23: {='Q2 - Plan on a Page'!I23:I28} -> 0 | P23: ='Q2 - Plan on a Page'!J23 -> 0 | Q23: {='Q3 - Plan on a Page'!E23:E28} -> 0 | R23: ='Q3 - Plan on a Page'!F23 -> 0 | S23: {='Q3 - Plan on a Page'!G23:G28} -> 0 | T23: ='Q3 - Plan on a Page'!H23 -> 0 | U23: {='Q3 - Plan on a Page'!I23:I28} -> 0 | V23: ='Q3 - Plan on a Page'!J23 -> 0 | W23: {='Q4 - Plan on a Page'!E23:E28} -> 0 | X23: ='Q4 - Plan on a Page'!F23 -> 0 | Y23: {='Q4 - Plan on a Page'!G23:G28} -> 0 | Z23: ='Q4 - Plan on a Page'!H23 -> 0 | AA23: {='Q4 - Plan on a Page'!I23:I28} -> 0 | AB23: ='Q4 - Plan on a Page'!J23 -> 0
B24: Paid Media - (Tradional) Fill in monthly Paid Media plan & budget | D24: Posters, Sidewalk Signs, Flyers, Direct Mailers, Door hangers, etc. | E24: ='Q1 - Plan on a Page '!E24 -> EXAMPLE: Distributed direct mailers to local neighborhoods | F24: ='Q1 - Plan on a Page '!F24 -> 200 | G24: 0 | H24: 0 | I24: 0 | J24: 0 | K24: 0 | L24: ='Q2 - Plan on a Page'!F24 -> 0 | M24: 0 | N24: ='Q2 - Plan on a Page'!H24 -> 0 | O24: 0 | P24: ='Q2 - Plan on a Page'!J24 -> 0 | Q24: 0 | R24: ='Q3 - Plan on a Page'!F24 -> 0 | S24: 0 | T24: ='Q3 - Plan on a Page'!H24 -> 0 | U24: 0 | V24: ='Q3 - Plan on a Page'!J24 -> 0 | W24: 0 | X24: ='Q4 - Plan on a Page'!F24 -> 0 | Y24: 0 | Z24: ='Q4 - Plan on a Page'!H24 -> 0 | AA24: 0 | AB24: ='Q4 - Plan on a Page'!J24 -> 0
B25: Community Marketing - B2B Partnerships Fill in monthly B2B Partnership plan & budget | D25: Plan ahead to order print assets and branded swag (flyers, business cards etc.) | E25: ='Q1 - Plan on a Page '!E25 -> EXAMPLE: Doorhangers for Carwash partnership (hang in rearview mirrors) | F25: ='Q1 - Plan on a Page '!F25 -> 100 | G25: 0 | H25: 0 | I25: 0 | J25: 0 | K25: 0 | L25: ='Q2 - Plan on a Page'!F25 -> 0 | M25: 0 | N25: ='Q2 - Plan on a Page'!H25 -> 0 | O25: 0 | P25: ='Q2 - Plan on a Page'!J25 -> 0 | Q25: 0 | R25: ='Q3 - Plan on a Page'!F25 -> 0 | S25: 0 | T25: ='Q3 - Plan on a Page'!H25 -> 0 | U25: 0 | V25: ='Q3 - Plan on a Page'!J25 -> 0 | W25: 0 | X25: ='Q4 - Plan on a Page'!F25 -> 0 | Y25: 0 | Z25: ='Q4 - Plan on a Page'!H25 -> 0 | AA25: 0 | AB25: ='Q4 - Plan on a Page'!J25 -> 0
B26: Community Marketing - Community Events #1 Fill in monthly Community Event plan & budget | D26: Plan ahead to order print assets and branded swag (price presentation sheets, swag, yard signs, banners, business cards, etc.) | E26: ='Q1 - Plan on a Page '!E26 -> EXAMPLE: Sponsor local sports team & table at game | F26: ='Q1 - Plan on a Page '!F26 -> 100 | G26: 0 | H26: 0 | I26: 0 | J26: 0 | K26: 0 | L26: ='Q2 - Plan on a Page'!F26 -> 0 | M26: 0 | N26: ='Q2 - Plan on a Page'!H26 -> 0 | O26: 0 | P26: ='Q2 - Plan on a Page'!J26 -> 0 | Q26: 0 | R26: ='Q3 - Plan on a Page'!F26 -> 0 | S26: 0 | T26: ='Q3 - Plan on a Page'!H26 -> 0 | U26: 0 | V26: ='Q3 - Plan on a Page'!J26 -> 0 | W26: 0 | X26: ='Q4 - Plan on a Page'!F26 -> 0 | Y26: 0 | Z26: ='Q4 - Plan on a Page'!H26 -> 0 | AA26: 0 | AB26: ='Q4 - Plan on a Page'!J26 -> 0
B27: Community Marketing - Community Events #2 Fill in monthly Community Event plan & budget | E27: ='Q1 - Plan on a Page '!E27 -> EXAMPLE: Host AF WorkOut | F27: ='Q1 - Plan on a Page '!F27 -> 50 | G27: 0 | H27: 0 | I27: 0 | J27: 0 | K27: 0 | L27: ='Q2 - Plan on a Page'!F27 -> 0 | M27: 0 | N27: ='Q2 - Plan on a Page'!H27 -> 0 | O27: 0 | P27: ='Q2 - Plan on a Page'!J27 -> 0 | Q27: 0 | R27: ='Q3 - Plan on a Page'!F27 -> 0 | S27: 0 | T27: ='Q3 - Plan on a Page'!H27 -> 0 | U27: 0 | V27: ='Q3 - Plan on a Page'!J27 -> 0 | W27: 0 | X27: ='Q4 - Plan on a Page'!F27 -> 0 | Y27: 0 | Z27: ='Q4 - Plan on a Page'!H27 -> 0 | AA27: 0 | AB27: ='Q4 - Plan on a Page'!J27 -> 0
B28: Community Marketing - Community Events #3 Fill in monthly Community Event plan & budget | E28: ='Q1 - Plan on a Page '!E28 -> EXAMPLE: Donation Center Dropoff | F28: ='Q1 - Plan on a Page '!F28 -> 50 | G28: 0 | H28: 0 | I28: 0 | J28: 0 | K28: 0 | L28: ='Q2 - Plan on a Page'!F28 -> 0 | M28: 0 | N28: ='Q2 - Plan on a Page'!H28 -> 0 | O28: 0 | P28: ='Q2 - Plan on a Page'!J28 -> 0 | Q28: 0 | R28: ='Q3 - Plan on a Page'!F28 -> 0 | S28: 0 | T28: ='Q3 - Plan on a Page'!H28 -> 0 | U28: 0 | V28: ='Q3 - Plan on a Page'!J28 -> 0 | W28: 0 | X28: ='Q4 - Plan on a Page'!F28 -> 0 | Y28: 0 | Z28: ='Q4 - Plan on a Page'!H28 -> 0 | AA28: 0 | AB28: ='Q4 - Plan on a Page'!J28 -> 0
B29: TOTAL | F29: =SUM(F23:F28) -> 2500 | H29: =SUM(H23:H28) -> 0 | J29: =SUM(J23:J28) -> 0 | L29: =SUM(L23:L28) -> 0 | N29: =SUM(N23:N28) -> 0 | P29: =SUM(P23:P28) -> 0 | R29: =SUM(R23:R28) -> 0 | T29: =SUM(T23:T28) -> 0 | V29: =SUM(V23:V28) -> 0 | X29: =SUM(X23:X28) -> 0 | Z29: =SUM(Z23:Z28) -> 0 | AB29: =SUM(AB23:AB28) -> 0

Sheet Local Business List
A1: BUSINESS NAME | B1: BUSINESS TYPE | C1: CONTACT | D1: CONTACT EMAIL | E1: CONTACT PHONE | F1: DISTANCE FROM CLUB (miles) | G1: NOTES
A2: Example: Restore Cryotherapy | B2: Wellness | C2: John Doe | D2: J.Doe@gmail.com | E2: 123-456-7891 | F2: 3 | G2: Met at Chamber of Commerce event in February

Sheet Local Event List
A1: EVENT NAME | B1: COST TO ATTEND | C1: EVENT DATE | D1: EVENT GOAL | E1: DISTANCE FROM CLUB (miles) | F1: NOTES
A2: Example Event #1 | B2: 75 | C2: 45749 | D2: Leads | E2: 6 | F2: Ashley and Amber to attend

Sheet Assets
A1: Community Marketing Customizable Templates
A2: Price Presentation Sheet | D2: Door Hanger | G2: Flyer | J2: Direct Mail | M2: Welcome Neighbor Direct Mail | P2: Outdoor Banner | S2: Yard Sign | V2: Sidewalk Sign | X2: Outdoor Workouts Sidewalk Sign
A3: TM22050006449076 | D3: TM22060017189296 | G3: TM22070002997647 | J3: TM23030010914060 | M3: TM23010007098604 | P3: TM22070004325530 | S3: TM22070000790885 | V3: TM22070005163969 | X3: TM23070003313981
A16: Social Media Customizable Templates | J16: Social 1200x1200
A17: Social 1080x1920 | D17: Social 1080x1920 | G17: Social 1200x1200 | J17: TM22070002972996
A18: TM24110002894983 | D18: TM22070002257745 | G18: TM22070002284427
A31: Community Marketing Swag
A32: AF RUBBERIZED SUNGLASSES | E32: AF KETTLEBELL SQUEEZIE | H32: AF Lip Balm | K32: AF Aluminum Bottle Opener Keychain | O32: Anytime Fitness Carabiner Keychain | R32: AF 12oz Slim Neoprene Can Cooler Multi | V32: AF Dart Pen Black | X32: AF Non-Woven Tote | Z32: AF Promo Cooler Bag
A33: Item 1460243-00 | E33: Item 1460241-00 | H33: Item 1462434-00 | K33: Item 1462425-00 | O33: Item 1462433-00 | R33: Item 1457632-00 | V33: Item 1457643-00 | X33: Item 1548115-00 | Z33: Item 1462432-00
A40: Community Marketing Apparel
A41: AF Unisex Promo Purple Tee | E41: AF Unisex Promo Tee Black
A42: Item 1553003 | E42: Item 1457638

Sheet 3 - Preferred Partners
C4: Preferred Partners for Local Marketing
C5: Feeling overwhelmed planning your marketing plan? Our preferred partners are here to help you strategize and plan your paid media tactics. You don't have to go it alone.
C6: Benefits of Partnering
C7: Choose among trusted experts – preferred partners must pass a rigorous selection process, leaving you with a selection of experts you know you can trust allowing you to focus on other important areas of your business. Save time and effort – by letting an expert take care of marketing your club, you get time back to invest in other important areas of your business Personalized recommendations – our preferred partners will create a program specific to your market. This includes review of zip code priorities and competitive analysis. Complement vs. compete, with local search keyword winning – preferred partners provide a zip code list to the corporate agency to allow local search campaigns to win keywords over the corporate campaigns for each location. When working with an outside vendor, corporate and local search campaigns bid against each other for keywords instead of working together. Lead source tracking – full visibility to your media performance and the true value of your cost per lead (CPL). Given restrictions with Google’s platform, we're only able to offer this tracking capability for our preferred media partners. Other digital agencies you may choose to partner with aren't able to provide an accurate CPL for paid search. Fair pre-negotiated media fees​ – the flat fee structure saves you money. If you decide to increase your budget on your local paid media, your agency fee stays the same no matter what. AF partnership and strategy – the AF local marketing team works with our preferred partners on a weekly basis to leverage system-wide platform learnings and apply them to your individual campaigns.
C8: Keepbooked - Digital paid media partner
C9: Keepbooked is a digital marketing agency created by Anytime Fitness owners, for Anytime Fitness owners. Established in 2021, the agency was created to address the specific challenges and opportunities of AF locations. They help customers develop a unique digital marketing strategy for each of their locations using paid search and paid social media. To help you capture and convert existing demand in your market and create new, targeted awareness in your local market, Keepbooked offers these services: Paid search – targeted lead generation through sponsored Google search results Paid social – local targeted advertising on Facebook and Instagram, on both mobile apps and desktop
C10: Contact Keepbooked
C12: Socius (previously Qiigo) - Digital paid media partner
C13: Socius currently works with more than 50+ brands and over 7,000 locations. Their unique approach to digital marketing allows you to take advantage of one-on-one support with localized campaigns, while still getting the benefit of group pricing and AF corporate support as well. To help you capture and convert existing demand in your market and create new, targeted awareness in your local market, Socius offers these services: Paid search – targeted lead generation through sponsored Google search results Paid social – local targeted advertising on Facebook and Instagram, on both mobile apps and desktop
C14: Contact Socius
C16: Asher - Digital + Traditional paid media partner
C17: The Asher Agency believes that the key to a successful partnership is going beyond the ad to truly understand the business. They know that making cash registers ring isn’t just about price points and pretty pictures. It requires truly understanding the local marketplace, careful planning, flawless execution, and detailed analysis. They've built a world-class division of professionals who share not only a passion for marketing but who relish all the finer points of the franchise world. To help you capture and convert existing demand in your market and create new, targeted awareness in your local market, Asher offers these services: Paid Search – targeted lead generation through sponsored Google search results Paid Social – local targeted advertising on Facebook, Instagram, and mobile apps Throughout the year, there are times when additional awareness is needed to promote various campaigns or happenings in your market. The Asher Agency can help you round out your campaigns during key times of year with locally focused billboards, direct mail, radio, TV and other media opportunities. Traditional Media – Tactics to drive local awareness and consideration. Tactics include, Direct Mail, Streaming Audio, Streaming Video, Billboards
... C26: Contact Direct2You

Sheet 4 - Goals, Tracking & ROAS- Exp
B8: MARKETING GOAL SETTING, TRACKING & CALCULATING ROAS
B11: TABLE 1 | C11: Set Your Goal | I11: TABLE 2 | J11: Key Inputs | Q11: TABLE 3 | R11: Planned Marketing Tactics to Drive Leads | V11: TABLE 4 | W11: Calculate Return on Ad Spend (ROAS)
B12: Set your Goal | C12: Recommended goals listed below | I12: Enter Key Inputs | J12: 1. NEW member goal | N12: =G13 -> 20 | O12: =DAY(EOMONTH(#REF!,0)) -> #REF! | Q12: Plan How You Will Get Your Leads | R12: Marketing Tactics | S12: Lead Goal | T12: Actual Leads | V12: Determine the return on ad spend of your marketing activities | W12: 1: Club Lifetime Value (LTV) | X12: Member Lifetime Value | Z12: 900
C13: New member goal | G13: 20 | J13: 2. Average scheduled appointment % | N13: 0.3
C14: Cost Per Lead (CPL) | G14: 35 | J14: 3. Average appt show % | N14: 0.45 | R14: 1. Digital Paid Media channels (search & social) | S14: 28 | T14: 28 | W14: 2: Marketing Budget *Not including agency fees | X14: Marketing Budget | Z14: 1300
J15: 4. Average monthly walk-ins | N15: 20
C16: Lead to member conversion goal | G16: 0.2 | J16: 5. Average lead to member conversion rate | N16: 0.2 | R16: 2. Traditional Paid Media tactics | S16: 30 | T16: 15 | W16: 3: Total leads | X16: Total leads driven from marketing tactics | Z16: =T24 -> 101
J17: 6.Total leads needed | N17: =N12/N16 -> 100
R18: 3. Community Events | S18: 40 | T18: 20 | W18: 4: Determine Cost Per Lead (CPL) | X18: (total budget/total leads) | Z18: =Z14/Z16 -> 12.871287
R20: 4. B2B Partnerships | S20: 25 | T20: 18 | W20: 5: Club conversion rate | X20: Lead to member conversion rate | Z20: =N16 -> 0.2
B22: COLOR CODE KEY | R22: 5.Street Team (parks, business area, parking lots, luxury apts, sidewalk hustle) | S22: 20 | T22: 20 | W22: 6: Calculate leads converted to members | X22: (Total Leads X Rate of Close = Total New Members) | Z22: =Z16*Z20 -> 20.2
B23: Owner/Manager to add Goal Info
R24: Total Leads | S24: =SUM(S14:S23) -> 143 | T24: =SUM(T14:T23) -> 101 | W24: 7: Revenue Driven | X24: (New Members X LTV = Money Generated) | Z24: =Z22*Z12 -> 18180
B25: Pull Club Data from Club OS
B26: Auto populates | W26: 8: Calculate Return on Ad Spend (ROAS) | X26: (Amount Gained - Amount Spent) / Amount Spent | Z26: =(Z24-Z14)/Z14 -> 12.984615
B29: KEY TERMS | I29: TABLE 2 INSTRUCTIONS | Q29: TABLE 3 INSTRUCTIONS | V29: TABLE 4 INSTRUCTIONS
B30: Cost Per Lead (CPL): The amount of money you pay for a lead to come to your club. To calculate your CPL, take your total budget and divide it by your total leads (Total Budget/Total Leads). Lifetime Value (LTV): The total amount a member will give your club over the tenure of their contract. Return on Ad Spend (ROAS): Total revenue for every dollar spent on marketing. *This dollar amount does not include paid media partner management fees | I30: 1. Set your new member goal 2 - 5 Find your club's averages by going to: Club OS > Dashboard > Sales Performance > New Leads and using the following filters: Location: Your Clubs Employee: All Marketing Source: All User Origin: All Date Rage: Custom (We recommend choosing 1 month during a similar time frame) 6. Total leads needed to meet member goal will auto populate | Q30: **Before you fill out Table 3, complete the "Plan on a Page" tab to determine your marketing tactics** 1. In column S, enter calculated digital paid media goal (paid media budget divided by clubs digital paid media CPL. AF's steady state digital paid CPL goal is $35 (search and social combined)) 2. In column S, enter traditional paid media lead goal based on club's previous performance 3. In column S, enter Community event lead goal based on club's previous performance or 10% of people you interact with at event 4. In column S, enter business/influencer partnership lead goal based on club's previous performance 5. In column S, enter street team goal based on club's previous performance Total Lead Goal Auto Populates **End of month enter actual leads in column T** Find your club's New Lead actuals per channel by going to: Club OS > Dashboard > Sales Performance > New Leads by Source (example: Web, Walk-in, App, Phone, Ads, Facebook, Referral) Total Actual Leads Auto Populates *If total actual leads meets or exceed your lead goal in "Table 2" the cell will turn green, if it is below the goal it will turn red | V30: 1. Determine club Lifetime value (LTV) Calculate LTV = monthly member dues X average length of member tenure. Average member tenure is 16 - 18 months (example: $50 X 18 = $900) 2. Enter monthly marketing budget as filled out in "Plan on a Page" *This total does not include agency fees 3. Auto populates Total Actual Leads when "Table 3" is completely filled out *If total actual leads meets or exceed your lead goal in "Table 2" the cell will turn green, if it is below the goal it will turn red 4. Auto populates Marketing campaign Cost Per Lead (CPL) by measuring the total marketing budget divided by the actual total leads 5. Auto populates member conversion rate as completed in "Table 2" 6. Auto populates leads converted to members (total actual leads multiplied by lead to member conversion rate) 7. Auto populates revenue driven from new members (new member total as populated above multiplied by Lifetime Value) 8. Auto populates the Return on Ad Spend (ROAS) for marketing campaign (total revenue minus marketing spend, divided by marketing spend = ROAS) $3 or higher is a good return on ad spend *if your ROAS meets or exceeds $3 the cell will turn green, if below it will turn red
I32: Example club dashboard - Woodbury, MN

Sheet 5 - Plan on a Page - Example
K2: Marketing Budget Spend Requirements
K3: FDD Requirement: Invest monthly spend investment (based on population) in local marketing tactics. *Recommended increase budget in Search and Social tactics during local promotions
K5: Based on Population Density 3-mile radius | M5: FDD Minimum Spend Requirement | O5: Recommended Budget (during local promotions*)
H6: COLOR CODE KEY | K6: Tier 1 / Urban (50,000<) | M6: $1,000 / month ($12,000 annually) | O6: $2,000 / month
B7: 2023 LOCAL MARKETING PLAN ON A PAGE | H7: Owner/Manager to add Goal Info | K7: Tier 2 / Suburban (25,000 - 49,999) | M7: $800 / month ($9,600 annually) | O7: $1,500 per / month
H8: Auto populates | K8: Tier 3 / Rural (<25,000) | M8: $600 / month ($7,200 annually) | O8: $800 / month
B10: STEP 1: Review the Corporate Marketing Calendar and Local Marketing Recommendations
E11: Q1 | H11: Q2 | K11: Q3 | N11: Q4
E12: JAN | F12: FEB | G12: MAR | H12: APR | I12: MAY | J12: JUN | K12: JUL | L12: AUG | M12: SEPT | N12: OCT | O12: NOV | P12: DEC
B13: Corporate Marketing (GAF Investment)
B14: Corporate Campaigns *Increased paid media investment during these times | C14: Increase awareness and consideration | E14: January Campaign | G14: Spring Campaign | L14: Fall Campaign | P14: January
B15: Steady State | C15: Maintain awareness and consideration | F15: Steady State - Paid Media | I15: Steady State - Paid Media | N15: Steady State - Paid Media
B17: Local Marketing *recommended timing of local promotions
B18: Local Club - Member Acquisition offer *Increase paid media investment during these times | C18: Bring in new members | E18: January Local Offer | H18: Spring Local Offer | M18: Fall Local Offer
B19: Local Club - PT Conversion Offer | C19: Drive new PT sign-ups | G19: 21-Day Reboot | J19: TNR Workshops | L19: AFWorkOUTs | O19: 21-Day Reboot
B21: STEP 2: Plan your Local Marketing promotions, tactics and budget
B22: Local Marketing Planning Calendar (Fill in the calendar with your local marketing promotions and tactics)
B23: Local Promotion (Fill in club's monthly local promotion) | E23: Join for $1 | G23: 7-Day Pass | I23: Join for $1 | K23: 7-Day Pass | M23: Join for $1 | O23: 7-Day Pass | P23: Join for $1
B24: Paid Media - Digital (Fill in monthly Digital Paid Media plan - FDD Minimum spend vs. Increased investment) | E24: Promo Reco Increase Investment ($1,000/month) | F24: FDD minimum - Steady State Investment ($600 / month) | H24: Promo Reco Increase Investment ($1,000/month) | J24: FDD minimum - Steady State Investment ($600 / month) | N24: Promo Reco Increase Investment ($1,000/month) | P24: FDD minimum - Steady State Investment ($600 / month)
B25: Paid Media - Traditional (Fill in monthly Traditional Paid Media Marketing tactics) | E25: sidewalk signs, flyers | H25: flyers & door hangers | N25: flyers & direct mail
B26: Community Marketing - B2B Partnerships (Fill in monthly B2B Partnership tactics) | E26: co-host social media contest with spray tanning salon | F26: community baskets | G26: community baskets | H26: Printing door hangers to put in cars at local car wash | I26: community baskets | J26: community baskets | K26: Host free group training for b2b partner's employees (drive new members) | L26: community baskets | M26: co-host social media contest with b2b partner | N26: community baskets | O26: send email to b2b partner's email list | P26: community baskets
B27: Community Marketing - Community Events (Fill in monthly Community Marketing tactics) | E27: Sponsor a 5k race & host a FREE group workout at club | H27: Host a community workout | J27: Tent at City Festival | L27: City Parade - Street Team | N27: Host Free group training | O27: co-host turkey trot | P27: Host Donation Drive - donators get free 1day pass
B28: Organic Social Media (Review monthly AF Social Media Planning Calendar) | E28: AF Social Media Monthly Planning Calendar
B29: Google Business Profile (Link to SOCi - Program Social Media Posts & Manage Google Business Profile) | E29: SOCi Login for platform management
B30: Local Marketing Budget | C30: Notes/Examples | D30: Yearly Marketing Budget
B31: Paid Media - Digital (Fill in monthly Digital Paid Media budget) | C31: Paid social/search | D31: =SUM(E31:P31) -> 9200 | E31: 1000 | F31: 600 | G31: 600 | H31: 1000 | I31: 1000 | J31: 600 | K31: 600 | L31: 600 | M31: 600 | N31: 1000 | O31: 1000 | P31: 600
B32: Paid Media - Traditional (Fill in monthly Traditional Paid Media budget) *Plan ahead for any printed materials | C32: Posters, Sidewalk Signs, Flyers, Direct Mailers, Door hangers, etc. | D32: =SUM(E32:P32) -> 600 | E32: 200 | G32: 200 | M32: 200
B33: Community Marketing - B2B Partnerships (Fill in monthly B2B Partnership budget) *Plan ahead for any printed materials | C33: Community baskets, swag, flyers, business cards, | D33: =SUM(E33:P33) -> 600 | E33: 50 | F33: 50 | G33: 50 | H33: 50 | I33: 50 | J33: 50 | K33: 50 | L33: 50 | M33: 50 | N33: 50 | O33: 50 | P33: 50
B34: Community Marketing - Community Events (Fill in monthly Community Event budget) *Plan ahead for any printed materials | C34: price presentation sheets, swag, yard signs, banners, business cards, etc. | D34: =SUM(E34:P34) -> 900 | E34: 50 | H34: 200 | J34: 100 | L34: 100 | M34: 150 | N34: 50 | O34: 200 | P34: 50
C35: TOTAL | D35: =SUM(D31:D34) -> 11300 | E35: =SUM(E31:E34) -> 1300 | F35: =SUM(F31:F34) -> 650 | G35: =SUM(G31:G34) -> 850 | H35: =SUM(H31:H34) -> 1250 | I35: =SUM(I31:I34) -> 1050 | J35: =SUM(J31:J34) -> 750 | K35: =SUM(K31:K34) -> 650 | ... P35: =SUM(P31:P34) -> 700
B38: STEP 3: On a monthly basis fill out the details of your local marketing tactics
B39: Step 1: Determine Your Goals | E39: Step 2: Plan Paid Media Digital & Traditional Media | I39: Step 3: Plan Community Marketing Community Events & B2B Partnerships | M39: Step 4: Plan Organic Social Media Plan Social Media Posts & Google Business Profile
B40: Determine 1-2 SMART Goal to focus your marketing efforts. (Specific, Measurable, Attainable, Relevant, Timely) Examples 1. 20 New Members - XX/XX-XX/XX 2. Paid Media CPL of $35 or less - XX/XX-XX/XX 3. Reach Lead to member conversion goal of 25% or greater - XX/XX-XX/XX Fill out Monthly Goal & Planned tactics to reach goal: | E40: Paid Media FDD Requirement: Invest monthly spend (based on population) in paid media tactics. Increase investment during seasonal campaigns Fill out Monthly Paid Media Plan: | I40: Community Marketing Requirement: 1-3 B2B Partnership Introductions & 2 Community Events per month Fill out Monthly Community Marketing Plans: | M40: Organic Social Media Requirement: Use SOCi to post to social media platforms, manage Google Business Profile and respond to reviews. Focus on 1-2 social media channels per month (Instagram / Facebook) and leverage the AF Social Media Planning Calendar to plan local social posts, don't forget to post about your community events as well! Fill out Social Media monthly plans:
B42: Month: January
B43: (example) Marketing Goal: Jan - Sell 20 New Memberships Jan 1st - Feb 28th | E43: (example) | I43: (example) | M43: (example)
E44: Paid Media Offer: Join for $1 | I44: Business Partnership Action Plan: 1. Co-host social media contest with spray tan salon - b2b partner PRIZE: (1) Free group training for winner + 5 friends & family 2. Local Health food store - Introduction 3. Local Self Care Business - Introduction (infrared, sauna, spray tan, waxing, massage, Cryo therapy) | M44: Social Media Post Calendar (Instagram & Facebook - Weekly)
E45: Digital Media Action Plan: Partnering with Qiigo with recommended investment of $1,000 for Jan Campaign Investment split between search & social | M45: Social Media Posts Action Plan: 1. Member success story - post 2. Back to the basics - video 3. Club Happenings (Community Event) - post & video 4. User generated content - post 5. FAQ - Post & video
B50: Tactics to reach Goal: 1. Digital Paid Media 2. Traditional Paid Media 3. Community Marketing Events (2) 4. Business Partnerships 5. Street Team | E50: Traditional Media Action Plan: $200 Order sidewalk signs from Brand Marketing Center & print flyers locally | I50: Community Events Action Plan: 1. Jan - Sponsor: 5k race 2. Jan - Host: free group workout at club | M50: Google Business Profile Action Plan: 1. Reply to reviews & questions (weekly) 2. Audit Google Business Profile Page (Monthly) 3. Update post with promotional offers & local events (when relevant) Post - Join for $1 local promotion Post - Community event: sponsored 5k race

Sheet 6 - Instructions
C4: Instructions on how to use the Local Marketing Planner
C5: The Local Marketing Planner will help you put your monthly marketing plan into place. With this tool, you can set your goals, outline your tactics and budget and then review your results all in one place. Owners and managers should work together to input your most recent club data, set goals, plan your marketing tactics and assess results. We encourage you to use this tool to create your yearly marketing plan outline. Then, each month save a copy of the Local Marketing Planner and add the month in the title. Use these monthly copied file to review your original plan and then add additional details for the month ahead. You can also then asses your previous month's results.
D6: How to complete the Local Marketing Planner Action 1: Complete Tables 1 & 2, and add Lifetime value (LTV) to Table 4 Action 2: Go to Tab 2 "Plan on a Page", review Step 1: "Corporate & Local Marketing Calendars", then fill out Step 2: "Local Marketing Planning Calendar" and "Local Marketing Budget" Action 3: Go to Tab 1 "Goals, Tracking & ROAS", Table 3: Lead goals. Add all anticipated leads per marketing tactics. Action 4: Add marketing budget to Table 4 Action 5: Execute your marketing tactics for the month. Action 6: Enter total actual leads at the end of the month to determine your results Action 7: Review the results of your marketing plan in Table 4 EXAMPLE: To review examples of how to complete each table, go to Tab 4: "Goals, Tracking & ROAS - Exp" & Tab 5: "Plan on a Page - Example"
C7: **Detailed Instructions on how to complete each tab below**
C8: Tab 1 "Goals, Tracking & ROAS"
C9: The Goal Setting and Tracking tab allows you to use current club data to set measurable goals, determine tactics for growth and assess your results/return on ad spend.
D11: Color Code Key
D12: Owner/Manager to add Goal Info
D13: Pull Club Data from Club OS
D14: Auto Populates
C16: TABLE 1 - Set Your Goal
D17: Determine 1-2 SMART Goals (Specific, Measurable, Achievable, Timebound) to focus on for the month
C19: TABLE 2 - Key Inputs
D20: 1. Enter your NEW member goal
D21: 2 - 5. Find your club's averages by going to: Club OS > Dashboard > Sales Performance > New Leads and using the following filters: "Location: Your Clubs Employee: All Marketing Source: All User Origin: All Date Rage: Custom (We recommend choosing 1 month during a similar time frame)
D22: Example club dashboard - Woodbury, MN
D34: 6. Total leads needed to meet member goal will auto populate
C37: TABLE 3 - Planned Marketing Tactics to Drive Leads
D38: **Before you fill out Table 3, complete the "Plan on a Page" tab to determine your marketing tactics for the month**
D39: 1. Fill in monthly Digital Paid Media Lead Goal in column S.
D40: (How to calculate: Digital paid media budget divided by your club's digital paid media CPL. (Pull this number from your agency report for CPL.) For general reference, AF's steady state digital paid CPL goal for search and social together is $35)
D42: 2. Fill in monthly traditional paid medial Lead Goal in column S based on club's previous performance.
D44: 3. Fill in monthly Community Event Lead Goal in column S based on club's previous performance or 10% of attendees you interacted with at the event.
D46: 4. Fill in monthly B2B Partnership Lead Goal in column S based on club's previous performance
D48: 5. Fill in monthly Street Team Lead Goal in column S based on club's previous performance
D50: 6. Total Lead Goal Auto Populates
D52: 7. At the end of the month enter actual leads in column "T"
D53: *If total actual leads meets or exceed your lead goal in "Table 2" the cell will turn green, if it is below the goal it will turn red as an indicator of performance.
D54: Find your club's New Lead actuals per channel by going to: Club OS > Dashboard > Sales Performance > New Leads by Source
D55: (example: Web, Walk-in, App, Phone, Ads, Facebook, Referral)
C69: TABLE 4 - Calculate return on ad spend
D70: 1. Determine club Lifetime value (LTV)
D71: Calculate LTV = monthly member dues X average length of member tenure. Average member tenure is 16 - 18 months
D72: (example: $50 X 18 = $900)
D73: To find your club's member tenure, click the link below for directions on how to pull the ABC report
D74: ABC Reporting Member Analysis
D76: 2. Enter monthly marketing budget as filled out in Tab 2: "Plan on a Page"
D77: *This total does not include agency fees
D79: 3. Table 4 auto populates Total Actual Leads when Table 3 is completely filled out
D80: *If total actual leads meets or exceeds your lead goal in Table 2 the cell will turn green, if it is below the goal it will turn red as an indicator of performance.
...
